Workbook
Name השכר_הסוציאלי_2023: 'תכנון פרישה (מקסימום תשואה)'!$B$13
Name שנות_עבודה_שנותרו: 'תכנון פרישה'!$B$2
Name השכר_הסוציאלי_2023: 'תכנון פרישה (מינימום תשואה)'!$B$13
Name קרן_פנסיה: 'תכנון פרישה (מינימום FU money)'!$B$7
Name גיל_הפנסיה: 'תכנון פרישה (מינימום FU money)'!$E$4
Name הגיל_שלנו_2023: 'תכנון פרישה (מינימום תשואה)'!$B$14
Name שיעור_משיכה_בטוח: 'תכנון פרישה (מקסימום תשואה)'!$B$15
Name קרן_פנסיה: 'תכנון פרישה (מינימום תשואה)'!$B$7
Name תשואה_ריאלית: 'תכנון פרישה (מינימום תשואה)'!$B$4
Name שנות_עבודה_שנותרו: 'תכנון פרישה (מינימום FU money)'!$B$2
Name קופת_גמל: 'תכנון פרישה (מינימום FU money)'!$B$8
Name הגיל_שלנו_2023: 'תכנון פרישה (מקסימום תשואה)'!$B$14
Name קופת_גמל: 'תכנון פרישה (מקסימום תשואה)'!$B$8
Name קופת_גמל: 'תכנון פרישה (מינימום תשואה)'!$B$8
Name שנות_עבודה_שנותרו: 'תכנון פרישה (מינימום תשואה)'!$B$2
Name קרן_פנסיה: 'תכנון פרישה'!$B$7
Name תשואה_ריאלית: 'תכנון פרישה'!$B$4
Name חסכון_נוכחי_2023: 'תכנון פרישה (מינימום תשואה)'!$B$5
Name שיעור_משיכה_בטוח: 'תכנון פרישה (מינימום תשואה)'!$B$15
Name תקרת_הפקדה_לפנסיה_בשנת_2023: 'תכנון פרישה (מקסימום תשואה)'!$K$4
Name חסכון_נוכחי_2023: 'תכנון פרישה (מינימום FU money)'!$B$5
Name שנות_עבודה_שנותרו: 'תכנון פרישה (מקסימום תשואה)'!$B$2
Name תקרת_הפקדה_לפנסיה_בשנת_2023: 'תכנון פרישה (מינימום תשואה)'!$K$4
Name הגיל_שלנו_2023: 'תכנון פרישה'!$B$14
Name חסכון_נוכחי_2023: 'תכנון פרישה (מקסימום תשואה)'!$B$5
Name שיעור_משיכה_בטוח: 'תכנון פרישה'!$B$15
Name הגיל_שלנו_2023: 'תכנון פרישה (מינימום FU money)'!$B$14
Name השכר_הסוציאלי_2023: 'תכנון פרישה'!$B$13
Name גיל_הפנסיה: 'תכנון פרישה'!$E$4
Name גיל_הפנסיה: 'תכנון פרישה (מינימום תשואה)'!$E$4
Name תקרת_הפקדה_לפנסיה_בשנת_2023: 'תכנון פרישה (מינימום FU money)'!$K$4
Name השכר_הסוציאלי_2023: 'תכנון פרישה (מינימום FU money)'!$B$13
Name תקרת_הפקדה_לפנסיה_בשנת_2023: 'תכנון פרישה'!$K$4
Name קופת_גמל: 'תכנון פרישה'!$B$8
Name תשואה_ריאלית: 'תכנון פרישה (מינימום FU money)'!$B$4
Name גיל_הפנסיה: 'תכנון פרישה (מקסימום תשואה)'!$E$4
Name חסכון_נוכחי_2023: 'תכנון פרישה'!$B$5
Name תשואה_ריאלית: 'תכנון פרישה (מקסימום תשואה)'!$B$4
Name שיעור_משיכה_בטוח: 'תכנון פרישה (מינימום FU money)'!$B$15
Name קרן_פנסיה: 'תכנון פרישה (מקסימום תשואה)'!$B$7

Sheet תכנון פרישה
I1: מהפרישה המוקדמת ועד גיל הפרישה (הפנסיה) | O1: בפנסיה
A2: שנות עבודה עד הפרישה | B2: 23 | D2: הכנסה חודשית ברוטו מפרישה ועד גיל פנסיה (לרמת החיים שהתרגלנו) | E2: 30000 | K2: חיסכון חודשי בעת העבודה | L2: מצב בעת הפרישה | Q2: מצב בעת היציאה לפנסיה
J3: קופות גמל | K3: =(8.33%+6%+6.5%)*'תכנון פרישה'!השכר_הסוציאלי_2023-'תכנון פרישה'!תקרת_הפקדה_לפנסיה_בשנת_2023 -> 4507.5 | L3: =fv($B$4,$B$2,-K3*12)+קופת_גמל*(1+$B$4)^$B$2 -> 2240974.4 | P3: קופות גמל | Q3: =L3*(1+'תכנון פרישה'!תשואה_ריאלית)^('תכנון פרישה'!גיל_הפנסיה-'תכנון פרישה'!שנות_עבודה_שנותרו-'תכנון פרישה'!הגיל_שלנו_2023) -> 3650311.2
A4: תשואה ריאלית על השקעות ונכסים | B4: 0.05 | D4: גיל למשיכת כספים סוציאליים (לפחות 60) | E4: 60 | J4: קרנות פנסיה | K4: 4866 | L4: =fv($B$4,$B$2,-K4*12)+קרן_פנסיה*(1+$B$4)^$B$2 -> 2879936.9 | P4: קרנות פנסיה | Q4: =L4*(1+'תכנון פרישה'!תשואה_ריאלית)^('תכנון פרישה'!גיל_הפנסיה-'תכנון פרישה'!שנות_עבודה_שנותרו-'תכנון פרישה'!הגיל_שלנו_2023) -> 4691113.7
A5: קרנות השתלמות | B5: 70000 | J5: קרן השתלמות | K5: =1571*2 -> 3142 | L5: =fv($B$4,$B$2,-K5*12)+B5*(1+$B$4)^$B$2 -> 1777101.3
A6: הון עצמי מושקע | B6: 100000 | J6: הון עצמי מושקע | K6: =-E12-sum(K3:K5) -> 4562.9038 | L6: =fv($B$4,$B$2,-K6*12)+B6*(1+$B$4)^$B$2 -> 2575671.6 | P6: פנסיה ברוטו | Q6: =SUM(Q3:Q4)/(202+4*(67-E4)) -> 36267.065
A7: קרנות פנסיה | B7: 150000
A8: קופת גמל \ ביטוחי מנהלים | J8: הון עצמי לשימושנו | K8: =L5+L6 -> 4352772.9
A9: ריבית משכנתא ממוצעת | B9: 0.045 | E9: מחושב | F9: באחוזים מהשכר | J9: למשך תקופה של | K9: =E4-B2-B14 -> 10 | L9: שנים
A10: יתרת משכנתא | B10: 900000 | D10: תשלום חודשי לבית | E10: =PMT(B9,$B$2,B10)/12 -> -5301.187 | F10: =-E10/$D$15 -> 0.10120711 | J10: בשיעור משיכה של | K10: =E2*12/K8 -> 0.082705899 | L10: בשנה
A11: סכום שיידרש בגיל הפרישה (כילוי מלא ללא השקעה) | B11: =E2*12*('תכנון פרישה'!גיל_הפנסיה-'תכנון פרישה'!הגיל_שלנו_2023-'תכנון פרישה'!שנות_עבודה_שנותרו) -> 3600000 | D11: תשלום חודשי להשקעות | E11: =PMT($B$4,$B$2, ,B11-($B$5*(1+$B$4)^$B$2))/12 -> -6808.5818 | F11: =-E11/$D$15 -> 0.12998539
A12: סכום שיידרש בגיל הפרישה (ללא כילוי) | B12: =E2*12/שיעור_משיכה_בטוח -> 9473684.2 | D12: תשלום חודשי להשקעות | E12: =PMT($B$4,$B$2, ,B12-(($B$5+$B$6+$B$7+$B$8)*(1+$B$4)^$B$2))/12 -> -17078.404 | F12: =-E12/$D$15 -> 0.32605073
A13: השכר הסוציאלי (ברוטו) למשק בית בממוצע לשנים האלו | B13: 45000
A14: הגיל היום | B14: 27 | D14: אז כמה נטו צריך בחודש בשביל זה (כולל קה"ש ופנסיה)?
A15: שיעור המשיכה הבטוח | B15: 0.038 | D15: =E2-E10-E12 -> 52379.591
D16: שכר בסיס נטו | E16: קרן השתלמות ופנסיה | F16: מניות ובונוסים נטו
D17: =55%*B13 -> 24750 | E17: =(20.833%)*B13+1571*2 -> 12516.85 | F17: =D15-D17-E17 -> 15112.741
E19: ברוטו בדולרים בשנה זה | F19: =F17*12*2/3.7 -> 98028.589
A20: הטבלה הזו - מראה טריידאוף בין עוצמת החיסכון לעוצמת התשואה (הריאלית)
A21: חסכון / תשואה | B21: 0.03 | C21: 0.04 | D21: 0.05 | E21: 0.06 | F21: 0.07 | G21: 0.08
A22: 0.1 | B22: =-FV(B$21,'תכנון פרישה'!שנות_עבודה_שנותרו,$D$15*12*$A22)+('תכנון פרישה'!חסכון_נוכחי_2023*(1+B$21)^'תכנון פרישה'!שנות_עבודה_שנותרו) -> 2177993.6 | C22: =-FV(C$21,'תכנון פרישה'!שנות_עבודה_שנותרו,$D$15*12*$A22)+('תכנון פרישה'!חסכון_נוכחי_2023*(1+C$21)^'תכנון פרישה'!שנות_עבודה_שנותרו) -> 2474166.1 | D22: =-FV(D$21,'תכנון פרישה'!שנות_עבודה_שנותרו,$D$15*12*$A22)+('תכנון פרישה'!חסכון_נוכחי_2023*(1+D$21)^'תכנון פרישה'!שנות_עבודה_שנותרו) -> 2819140.3 | E22: =-FV(E$21,'תכנון פרישה'!שנות_עבודה_שנותרו,$D$15*12*$A22)+('תכנון פרישה'!חסכון_נוכחי_2023*(1+E$21)^'תכנון פרישה'!שנות_עבודה_שנותרו) -> 3221329.1 | F22: =-FV(F$21,'תכנון פרישה'!שנות_עבודה_שנותרו,$D$15*12*$A22)+('תכנון פרישה'!חסכון_נוכחי_2023*(1+F$21)^'תכנון פרישה'!שנות_עבודה_שנותרו) -> 3690592.9 | G22: =-FV(G$21,'תכנון פרישה'!שנות_עבודה_שנותרו,$D$15*12*$A22)+('תכנון פרישה'!חסכון_נוכחי_2023*(1+G$21)^'תכנון פרישה'!שנות_עבודה_שנותרו) -> 4238481.5
A23: כמה נמשוך רק מהתשואה בגיל פרישה | B23: =B22*B$21/12 -> 5444.9839 | C23: =C22*C$21/12 -> 8247.2204 | D23: =D22*D$21/12 -> 11746.418 | E23: =E22*E$21/12 -> 16106.646 | F23: =F22*F$21/12 -> 21528.459 | G23: =G22*G$21/12 -> 28256.544
A24: ="כמה נמשוך כולל הקרן , מהפרישה ועד גיל "&$E$4&"" -> כמה נמשוך כולל הקרן , מהפרישה ועד גיל 60 | B24: =-PMT(B$21,'תכנון פרישה'!גיל_הפנסיה-'תכנון פרישה'!הגיל_שלנו_2023-'תכנון פרישה'!שנות_עבודה_שנותרו,B22)/12 -> 21277.274 | C24: =-PMT(C$21,'תכנון פרישה'!גיל_הפנסיה-'תכנון פרישה'!הגיל_שלנו_2023-'תכנון פרישה'!שנות_עבודה_שנותרו,C22)/12 -> 25420.19 | D24: =-PMT(D$21,'תכנון פרישה'!גיל_הפנסיה-'תכנון פרישה'!הגיל_שלנו_2023-'תכנון פרישה'!שנות_עבודה_שנותרו,D22)/12 -> 30424.297 | E24: =-PMT(E$21,'תכנון פרישה'!גיל_הפנסיה-'תכנון פרישה'!הגיל_שלנו_2023-'תכנון פרישה'!שנות_עבודה_שנותרו,E22)/12 -> 36472.951 | F24: =-PMT(F$21,'תכנון פרישה'!גיל_הפנסיה-'תכנון פרישה'!הגיל_שלנו_2023-'תכנון פרישה'!שנות_עבודה_שנותרו,F22)/12 -> 43788.117 | G24: =-PMT(G$21,'תכנון פרישה'!גיל_הפנסיה-'תכנון פרישה'!הגיל_שלנו_2023-'תכנון פרישה'!שנות_עבודה_שנותרו,G22)/12 -> 52638.228
A25: 0.15 | B25: =-FV(B$21,'תכנון פרישה'!שנות_עבודה_שנותרו,$D$15*12*$A25)+('תכנון פרישה'!חסכון_נוכחי_2023*(1+B$21)^'תכנון פרישה'!שנות_עבודה_שנותרו) -> 3197914.8 | C25: =-FV(C$21,'תכנון פרישה'!שנות_עבודה_שנותרו,$D$15*12*$A25)+('תכנון פרישה'!חסכון_נוכחי_2023*(1+C$21)^'תכנון פרישה'!שנות_עבודה_שנותרו) -> 3624984.1 | D25: =-FV(D$21,'תכנון פרישה'!שנות_עבודה_שנותרו,$D$15*12*$A25)+('תכנון פרישה'!חסכון_נוכחי_2023*(1+D$21)^'תכנון פרישה'!שנות_עבודה_שנותרו) -> 4121207.1 | E25: =-FV(E$21,'תכנון פרישה'!שנות_עבודה_שנותרו,$D$15*12*$A25)+('תכנון פרישה'!חסכון_נוכחי_2023*(1+E$21)^'תכנון פרישה'!שנות_עבודה_שנותרו) -> 4698302.5 | F25: =-FV(F$21,'תכנון פרישה'!שנות_עבודה_שנותרו,$D$15*12*$A25)+('תכנון פרישה'!חסכון_נוכחי_2023*(1+F$21)^'תכנון פרישה'!שנות_עבודה_שנותרו) -> 5369970.8 | G25: =-FV(G$21,'תכנון פרישה'!שנות_עבודה_שנותרו,$D$15*12*$A25)+('תכנון פרישה'!חסכון_נוכחי_2023*(1+G$21)^'תכנון פרישה'!שנות_עבודה_שנותרו) -> 6152221.1
A26: כמה נמשוך רק מהתשואה בגיל פרישה | B26: =B25*B$21/12 -> 7994.7871 | C26: =C25*C$21/12 -> 12083.28 | D26: =D25*D$21/12 -> 17171.696 | E26: =E25*E$21/12 -> 23491.512 | F26: =F25*F$21/12 -> 31324.83 | G26: =G25*G$21/12 -> 41014.807
A27: ="כמה נמשוך כולל הקרן , מהפרישה ועד גיל "&$E$4&"" -> כמה נמשוך כולל הקרן , מהפרישה ועד גיל 60 | B27: =-PMT(B$21,'תכנון פרישה'!גיל_הפנסיה-'תכנון פרישה'!הגיל_שלנו_2023-'תכנון פרישה'!שנות_עבודה_שנותרו,B25)/12 -> 31241.098 | C27: =-PMT(C$21,'תכנון פרישה'!גיל_הפנסיה-'תכנון פרישה'!הגיל_שלנו_2023-'תכנון פרישה'!שנות_עבודה_שנותרו,C25)/12 -> 37243.976 | D27: =-PMT(D$21,'תכנון פרישה'!גיל_הפנסיה-'תכנון פרישה'!הגיל_שלנו_2023-'תכנון פרישה'!שנות_עבודה_שנותרו,D25)/12 -> 44476.264 | E27: =-PMT(E$21,'תכנון פרישה'!גיל_הפנסיה-'תכנון פרישה'!הגיל_שלנו_2023-'תכנון פרישה'!שנות_עבודה_שנותרו,E25)/12 -> 53195.73 | F27: =-PMT(F$21,'תכנון פרישה'!גיל_הפנסיה-'תכנון פרישה'!הגיל_שלנו_2023-'תכנון פרישה'!שנות_עבודה_שנותרו,F25)/12 -> 63713.586 | G27: =-PMT(G$21,'תכנון פרישה'!גיל_הפנסיה-'תכנון פרישה'!הגיל_שלנו_2023-'תכנון פרישה'!שנות_עבודה_שנותרו,G25)/12 -> 76405.197
A28: 0.2 | B28: =-FV(B$21,'תכנון פרישה'!שנות_עבודה_שנותרו,$D$15*12*$A28)+('תכנון פרישה'!חסכון_נוכחי_2023*(1+B$21)^'תכנון פרישה'!שנות_עבודה_שנותרו) -> 4217836.1 | C28: =-FV(C$21,'תכנון פרישה'!שנות_עבודה_שנותרו,$D$15*12*$A28)+('תכנון פרישה'!חסכון_נוכחי_2023*(1+C$21)^'תכנון פרישה'!שנות_עבודה_שנותרו) -> 4775802.1 | D28: =-FV(D$21,'תכנון פרישה'!שנות_עבודה_שנותרו,$D$15*12*$A28)+('תכנון פרישה'!חסכון_נוכחי_2023*(1+D$21)^'תכנון פרישה'!שנות_עבודה_שנותרו) -> 5423273.9 | E28: =-FV(E$21,'תכנון פרישה'!שנות_עבודה_שנותרו,$D$15*12*$A28)+('תכנון פרישה'!חסכון_נוכחי_2023*(1+E$21)^'תכנון פרישה'!שנות_עבודה_שנותרו) -> 6175275.8 | F28: =-FV(F$21,'תכנון פרישה'!שנות_עבודה_שנותרו,$D$15*12*$A28)+('תכנון פרישה'!חסכון_נוכחי_2023*(1+F$21)^'תכנון פרישה'!שנות_עבודה_שנותרו) -> 7049348.8 | G28: =-FV(G$21,'תכנון פרישה'!שנות_עבודה_שנותרו,$D$15*12*$A28)+('תכנון פרישה'!חסכון_נוכחי_2023*(1+G$21)^'תכנון פרישה'!שנות_עבודה_שנותרו) -> 8065960.6
A29: כמה נמשוך רק מהתשואה בגיל פרישה | B29: =B28*B$21/12 -> 10544.59 | C29: =C28*C$21/12 -> 15919.34 | D29: =D28*D$21/12 -> 22596.974 | E29: =E28*E$21/12 -> 30876.379 | F29: =F28*F$21/12 -> 41121.201 | G29: =G28*G$21/12 -> 53773.071
A30: ="כמה נמשוך כולל הקרן , מהפרישה ועד גיל "&$E$4&"" -> כמה נמשוך כולל הקרן , מהפרישה ועד גיל 60 | B30: =-PMT(B$21,'תכנון פרישה'!גיל_הפנסיה-'תכנון פרישה'!הגיל_שלנו_2023-'תכנון פרישה'!שנות_עבודה_שנותרו,B28)/12 -> 41204.922 | C30: =-PMT(C$21,'תכנון פרישה'!גיל_הפנסיה-'תכנון פרישה'!הגיל_שלנו_2023-'תכנון פרישה'!שנות_עבודה_שנותרו,C28)/12 -> 49067.763 | D30: =-PMT(D$21,'תכנון פרישה'!גיל_הפנסיה-'תכנון פרישה'!הגיל_שלנו_2023-'תכנון פרישה'!שנות_עבודה_שנותרו,D28)/12 -> 58528.231 | E30: =-PMT(E$21,'תכנון פרישה'!גיל_הפנסיה-'תכנון פרישה'!הגיל_שלנו_2023-'תכנון פרישה'!שנות_עבודה_שנותרו,E28)/12 -> 69918.51 | F30: =-PMT(F$21,'תכנון פרישה'!גיל_הפנסיה-'תכנון פרישה'!הגיל_שלנו_2023-'תכנון פרישה'!שנות_עבודה_שנותרו,F28)/12 -> 83639.056 | G30: =-PMT(G$21,'תכנון פרישה'!גיל_הפנסיה-'תכנון פרישה'!הגיל_שלנו_2023-'תכנון פרישה'!שנות_עבודה_שנותרו,G28)/12 -> 100172.17
A31: 0.25 | B31: =-FV(B$21,'תכנון פרישה'!שנות_עבודה_שנותרו,$D$15*12*$A31)+('תכנון פרישה'!חסכון_נוכחי_2023*(1+B$21)^'תכנון פרישה'!שנות_עבודה_שנותרו) -> 5237757.4 | C31: =-FV(C$21,'תכנון פרישה'!שנות_עבודה_שנותרו,$D$15*12*$A31)+('תכנון פרישה'!חסכון_נוכחי_2023*(1+C$21)^'תכנון פרישה'!שנות_עבודה_שנותרו) -> 5926620.1 | D31: =-FV(D$21,'תכנון פרישה'!שנות_עבודה_שנותרו,$D$15*12*$A31)+('תכנון פרישה'!חסכון_נוכחי_2023*(1+D$21)^'תכנון פרישה'!שנות_עבודה_שנותרו) -> 6725340.7 | E31: =-FV(E$21,'תכנון פרישה'!שנות_עבודה_שנותרו,$D$15*12*$A31)+('תכנון פרישה'!חסכון_נוכחי_2023*(1+E$21)^'תכנון פרישה'!שנות_עבודה_שנותרו) -> 7652249.1 | F31: =-FV(F$21,'תכנון פרישה'!שנות_עבודה_שנותרו,$D$15*12*$A31)+('תכנון פרישה'!חסכון_נוכחי_2023*(1+F$21)^'תכנון פרישה'!שנות_עבודה_שנותרו) -> 8728726.7 | G31: =-FV(G$21,'תכנון פרישה'!שנות_עבודה_שנותרו,$D$15*12*$A31)+('תכנון פרישה'!חסכון_נוכחי_2023*(1+G$21)^'תכנון פרישה'!שנות_עבודה_שנותרו) -> 9979700.2
A32: כמה נמשוך רק מהתשואה בגיל פרישה | B32: =B31*B$21/12 -> 13094.393 | C32: =C31*C$21/12 -> 19755.4 | D32: =D31*D$21/12 -> 28022.253 | E32: =E31*E$21/12 -> 38261.246 | F32: =F31*F$21/12 -> 50917.572 | G32: =G31*G$21/12 -> 66531.334
A33: ="כמה נמשוך כולל הקרן , מהפרישה ועד גיל "&$E$4&"" -> כמה נמשוך כולל הקרן , מהפרישה ועד גיל 60 | B33: =-PMT(B$21,'תכנון פרישה'!גיל_הפנסיה-'תכנון פרישה'!הגיל_שלנו_2023-'תכנון פרישה'!שנות_עבודה_שנותרו,B31)/12 -> 51168.746 | C33: =-PMT(C$21,'תכנון פרישה'!גיל_הפנסיה-'תכנון פרישה'!הגיל_שלנו_2023-'תכנון פרישה'!שנות_עבודה_שנותרו,C31)/12 -> 60891.55 | D33: =-PMT(D$21,'תכנון פרישה'!גיל_הפנסיה-'תכנון פרישה'!הגיל_שלנו_2023-'תכנון פרישה'!שנות_עבודה_שנותרו,D31)/12 -> 72580.199 | E33: =-PMT(E$21,'תכנון פרישה'!גיל_הפנסיה-'תכנון פרישה'!הגיל_שלנו_2023-'תכנון פרישה'!שנות_עבודה_שנותרו,E31)/12 -> 86641.289 | F33: =-PMT(F$21,'תכנון פרישה'!גיל_הפנסיה-'תכנון פרישה'!הגיל_שלנו_2023-'תכנון פרישה'!שנות_עבודה_שנותרו,F31)/12 -> 103564.53 | G33: =-PMT(G$21,'תכנון פרישה'!גיל_הפנסיה-'תכנון פרישה'!הגיל_שלנו_2023-'תכנון פרישה'!שנות_עבודה_שנותרו,G31)/12 -> 123939.13
A34: 0.3 | B34: =-FV(B$21,'תכנון פרישה'!שנות_עבודה_שנותרו,$D$15*12*$A34)+('תכנון פרישה'!חסכון_נוכחי_2023*(1+B$21)^'תכנון פרישה'!שנות_עבודה_שנותרו) -> 6257678.6 | C34: =-FV(C$21,'תכנון פרישה'!שנות_עבודה_שנותרו,$D$15*12*$A34)+('תכנון פרישה'!חסכון_נוכחי_2023*(1+C$21)^'תכנון פרישה'!שנות_עבודה_שנותרו) -> 7077438.2 | D34: =-FV(D$21,'תכנון פרישה'!שנות_עבודה_שנותרו,$D$15*12*$A34)+('תכנון פרישה'!חסכון_נוכחי_2023*(1+D$21)^'תכנון פרישה'!שנות_עבודה_שנותרו) -> 8027407.5 | E34: =-FV(E$21,'תכנון פרישה'!שנות_עבודה_שנותרו,$D$15*12*$A34)+('תכנון פרישה'!חסכון_נוכחי_2023*(1+E$21)^'תכנון פרישה'!שנות_עבודה_שנותרו) -> 9129222.5 | F34: =-FV(F$21,'תכנון פרישה'!שנות_עבודה_שנותרו,$D$15*12*$A34)+('תכנון פרישה'!חסכון_נוכחי_2023*(1+F$21)^'תכנון פרישה'!שנות_עבודה_שנותרו) -> 10408105 | G34: =-FV(G$21,'תכנון פרישה'!שנות_עבודה_שנותרו,$D$15*12*$A34)+('תכנון פרישה'!חסכון_נוכחי_2023*(1+G$21)^'תכנון פרישה'!שנות_עבודה_שנותרו) -> 11893440
A35: כמה נמשוך רק מהתשואה בגיל פרישה | B35: =B34*B$21/12 -> 15644.197 | C35: =C34*C$21/12 -> 23591.461 | D35: =D34*D$21/12 -> 33447.531 | E35: =E34*E$21/12 -> 45646.112 | F35: =F34*F$21/12 -> 60713.943 | G35: =G34*G$21/12 -> 79289.598
A36: ="כמה נמשוך כולל הקרן , מהפרישה ועד גיל "&$E$4&"" -> כמה נמשוך כולל הקרן , מהפרישה ועד גיל 60 | B36: =-PMT(B$21,'תכנון פרישה'!גיל_הפנסיה-'תכנון פרישה'!הגיל_שלנו_2023-'תכנון פרישה'!שנות_עבודה_שנותרו,B34)/12 -> 61132.57 | C36: =-PMT(C$21,'תכנון פרישה'!גיל_הפנסיה-'תכנון פרישה'!הגיל_שלנו_2023-'תכנון פרישה'!שנות_עבודה_שנותרו,C34)/12 -> 72715.336 | D36: =-PMT(D$21,'תכנון פרישה'!גיל_הפנסיה-'תכנון פרישה'!הגיל_שלנו_2023-'תכנון פרישה'!שנות_עבודה_שנותרו,D34)/12 -> 86632.166 | E36: =-PMT(E$21,'תכנון פרישה'!גיל_הפנסיה-'תכנון פרישה'!הגיל_שלנו_2023-'תכנון פרישה'!שנות_עבודה_שנותרו,E34)/12 -> 103364.07 | F36: =-PMT(F$21,'תכנון פרישה'!גיל_הפנסיה-'תכנון פרישה'!הגיל_שלנו_2023-'תכנון פרישה'!שנות_עבודה_שנותרו,F34)/12 -> 123489.99 | G36: =-PMT(G$21,'תכנון פרישה'!גיל_הפנסיה-'תכנון פרישה'!הגיל_שלנו_2023-'תכנון פרישה'!שנות_עבודה_שנותרו,G34)/12 -> 147706.1
A37: 0.35 | B37: =-FV(B$21,'תכנון פרישה'!שנות_עבודה_שנותרו,$D$15*12*$A37)+('תכנון פרישה'!חסכון_נוכחי_2023*(1+B$21)^'תכנון פרישה'!שנות_עבודה_שנותרו) -> 7277599.9 | C37: =-FV(C$21,'תכנון פרישה'!שנות_עבודה_שנותרו,$D$15*12*$A37)+('תכנון פרישה'!חסכון_נוכחי_2023*(1+C$21)^'תכנון פרישה'!שנות_עבודה_שנותרו) -> 8228256.2 | D37: =-FV(D$21,'תכנון פרישה'!שנות_עבודה_שנותרו,$D$15*12*$A37)+('תכנון פרישה'!חסכון_נוכחי_2023*(1+D$21)^'תכנון פרישה'!שנות_עבודה_שנותרו) -> 9329474.3 | E37: =-FV(E$21,'תכנון פרישה'!שנות_עבודה_שנותרו,$D$15*12*$A37)+('תכנון פרישה'!חסכון_נוכחי_2023*(1+E$21)^'תכנון פרישה'!שנות_עבודה_שנותרו) -> 10606196 | F37: =-FV(F$21,'תכנון פרישה'!שנות_עבודה_שנותרו,$D$15*12*$A37)+('תכנון פרישה'!חסכון_נוכחי_2023*(1+F$21)^'תכנון פרישה'!שנות_עבודה_שנותרו) -> 12087482 | G37: =-FV(G$21,'תכנון פרישה'!שנות_עבודה_שנותרו,$D$15*12*$A37)+('תכנון פרישה'!חסכון_נוכחי_2023*(1+G$21)^'תכנון פרישה'!שנות_עבודה_שנותרו) -> 13807179
A38: כמה נמשוך רק מהתשואה בגיל פרישה | B38: =B37*B$21/12 -> 18194 | C38: =C37*C$21/12 -> 27427.521 | D38: =D37*D$21/12 -> 38872.809 | E38: =E37*E$21/12 -> 53030.979 | F38: =F37*F$21/12 -> 70510.315 | G38: =G37*G$21/12 -> 92047.862
A39: ="כמה נמשוך כולל הקרן , מהפרישה ועד גיל "&$E$4&"" -> כמה נמשוך כולל הקרן , מהפרישה ועד גיל 60 | B39: =-PMT(B$21,'תכנון פרישה'!גיל_הפנסיה-'תכנון פרישה'!הגיל_שלנו_2023-'תכנון פרישה'!שנות_עבודה_שנותרו,B37)/12 -> 71096.393 | C39: =-PMT(C$21,'תכנון פרישה'!גיל_הפנסיה-'תכנון פרישה'!הגיל_שלנו_2023-'תכנון פרישה'!שנות_עבודה_שנותרו,C37)/12 -> 84539.123 | D39: =-PMT(D$21,'תכנון פרישה'!גיל_הפנסיה-'תכנון פרישה'!הגיל_שלנו_2023-'תכנון פרישה'!שנות_עבודה_שנותרו,D37)/12 -> 100684.13 | E39: =-PMT(E$21,'תכנון פרישה'!גיל_הפנסיה-'תכנון פרישה'!הגיל_שלנו_2023-'תכנון פרישה'!שנות_עבודה_שנותרו,E37)/12 -> 120086.85 | F39: =-PMT(F$21,'תכנון פרישה'!גיל_הפנסיה-'תכנון פרישה'!הגיל_שלנו_2023-'תכנון פרישה'!שנות_עבודה_שנותרו,F37)/12 -> 143415.46 | G39: =-PMT(G$21,'תכנון פרישה'!גיל_הפנסיה-'תכנון פרישה'!הגיל_שלנו_2023-'תכנון פרישה'!שנות_עבודה_שנותרו,G37)/12 -> 171473.07
A40: 0.4 | B40: =-FV(B$21,'תכנון פרישה'!שנות_עבודה_שנותרו,$D$15*12*$A40)+('תכנון פרישה'!חסכון_נוכחי_2023*(1+B$21)^'תכנון פרישה'!שנות_עבודה_שנותרו) -> 8297521.1 | C40: =-FV(C$21,'תכנון פרישה'!שנות_עבודה_שנותרו,$D$15*12*$A40)+('תכנון פרישה'!חסכון_נוכחי_2023*(1+C$21)^'תכנון פרישה'!שנות_עבודה_שנותרו) -> 9379074.2 | D40: =-FV(D$21,'תכנון פרישה'!שנות_עבודה_שנותרו,$D$15*12*$A40)+('תכנון פרישה'!חסכון_נוכחי_2023*(1+D$21)^'תכנון פרישה'!שנות_עבודה_שנותרו) -> 10631541 | E40: =-FV(E$21,'תכנון פרישה'!שנות_עבודה_שנותרו,$D$15*12*$A40)+('תכנון פרישה'!חסכון_נוכחי_2023*(1+E$21)^'תכנון פרישה'!שנות_עבודה_שנותרו) -> 12083169 | F40: =-FV(F$21,'תכנון פרישה'!שנות_עבודה_שנותרו,$D$15*12*$A40)+('תכנון פרישה'!חסכון_נוכחי_2023*(1+F$21)^'תכנון פרישה'!שנות_עבודה_שנותרו) -> 13766860 | G40: =-FV(G$21,'תכנון פרישה'!שנות_עבודה_שנותרו,$D$15*12*$A40)+('תכנון פרישה'!חסכון_נוכחי_2023*(1+G$21)^'תכנון פרישה'!שנות_עבודה_שנותרו) -> 15720919
A41: כמה נמשוך רק מהתשואה בגיל פרישה | B41: =B40*B$21/12 -> 20743.803 | C41: =C40*C$21/12 -> 31263.581 | D41: =D40*D$21/12 -> 44298.088 | E41: =E40*E$21/12 -> 60415.846 | F41: =F40*F$21/12 -> 80306.686 | G41: =G40*G$21/12 -> 104806.13
...

Sheet תכנון פרישה (מינימום FU money)
I1: מהפרישה המוקדמת ועד גיל הפרישה (הפנסיה) | O1: בפנסיה
A2: שנות עבודה עד הפרישה | B2: 4.5 | D2: הכנסה חודשית ברוטו מפרישה ועד גיל פנסיה (לרמת החיים שהתרגלנו) | E2: 20000 | K2: חיסכון חודשי בעת העבודה | L2: מצב בעת הפרישה | Q2: מצב בעת היציאה לפנסיה
J3: קופות גמל | K3: =(8.33%+6%+6.5%)*'תכנון פרישה (מינימום FU money)'!השכר_הסוציאלי_2023-'תכנון פרישה (מינימום FU money)'!תקרת_הפקדה_לפנסיה_בשנת_2023 -> 4507.5 | L3: =fv($B$4,$B$2,-K3*12)+'תכנון פרישה (מינימום FU money)'!קופת_גמל*(1+$B$4)^$B$2 -> 265607.07 | P3: קופות גמל | Q3: =L3*(1+'תכנון פרישה (מינימום FU money)'!תשואה_ריאלית)^('תכנון פרישה (מינימום FU money)'!גיל_הפנסיה-'תכנון פרישה (מינימום FU money)'!שנות_עבודה_שנותרו-'תכנון פרישה (מינימום FU money)'!הגיל_שלנו_2023) -> 1066926.9
A4: תשואה ריאלית על השקעות ונכסים | B4: 0.05 | D4: גיל למשיכת כספים סוציאליים (לפחות 60) | E4: 60 | J4: קרנות פנסיה | K4: 4866 | L4: =fv($B$4,$B$2,-K4*12)+'תכנון פרישה (מינימום FU money)'!קרן_פנסיה*(1+$B$4)^$B$2 -> 473560.39 | P4: קרנות פנסיה | Q4: =L4*(1+'תכנון פרישה (מינימום FU money)'!תשואה_ריאלית)^('תכנון פרישה (מינימום FU money)'!גיל_הפנסיה-'תכנון פרישה (מינימום FU money)'!שנות_עבודה_שנותרו-'תכנון פרישה (מינימום FU money)'!הגיל_שלנו_2023) -> 1902262.2
A5: קרנות השתלמות | B5: ='תכנון פרישה'!B5 -> 70000 | J5: קרן השתלמות | K5: =1571*2 -> 3142 | L5: =fv($B$4,$B$2,-K5*12)+B5*(1+$B$4)^$B$2 -> 272330.82
A6: הון עצמי מושקע | B6: ='תכנון פרישה'!B6 -> 100000 | J6: הון עצמי מושקע | K6: =-E12-sum(K3:K5) -> 87903.054 | L6: =fv($B$4,$B$2,-K6*12)+B6*(1+$B$4)^$B$2 -> 5304291.2 | P6: פנסיה ברוטו | Q6: =SUM(Q3:Q4)/(202+4*(67-E4)) -> 12909.518
A7: קרנות פנסיה | B7: ='תכנון פרישה'!B7 -> 150000
A8: קופת גמל \ ביטוחי מנהלים | B8: ='תכנון פרישה'!B8 | J8: הון עצמי לשימושנו | K8: =L5+L6 -> 5576622
A9: ריבית משכנתא ממוצעת | B9: ='תכנון פרישה'!B9 -> 0.045 | E9: מחושב | F9: באחוזים מהשכר | J9: למשך תקופה של | K9: =E4-B2-B14 -> 28.5 | L9: שנים
A10: יתרת משכנתא | B10: ='תכנון פרישה'!B10 -> 900000 | D10: תשלום חודשי לבית | E10: =PMT(B9,$B$2,B10)/12 -> -18782.088 | F10: =-E10/$D$15 -> 0.13492817 | J10: בשיעור משיכה של | K10: =E2*12/K8 -> 0.043036806 | L10: בשנה
A11: סכום שיידרש בגיל הפרישה (כילוי מלא ללא השקעה) | B11: =E2*12*('תכנון פרישה (מינימום FU money)'!גיל_הפנסיה-'תכנון פרישה (מינימום FU money)'!הגיל_שלנו_2023-'תכנון פרישה (מינימום FU money)'!שנות_עבודה_שנותרו) -> 6840000 | D11: תשלום חודשי להשקעות | E11: =PMT($B$4,$B$2, ,B11-($B$5*(1+$B$4)^$B$2))/12 -> -114599 | F11: =-E11/$D$15 -> 0.82326491
A12: סכום שיידרש בגיל הפרישה (ללא כילוי) | B12: =E2*12/'תכנון פרישה (מינימום FU money)'!שיעור_משיכה_בטוח -> 6315789.5 | D12: תשלום חודשי להשקעות | E12: =PMT($B$4,$B$2, ,B12-(($B$5+$B$6+$B$7+$B$8)*(1+$B$4)^$B$2))/12 -> -100418.55 | F12: =-E12/$D$15 -> 0.72139433
A13: השכר הסוציאלי (ברוטו) למשק בית בממוצע לשנים האלו | B13: ='תכנון פרישה'!B13 -> 45000
A14: הגיל היום | B14: ='תכנון פרישה'!B14 -> 27 | D14: אז כמה נטו צריך בחודש בשביל זה (כולל קה"ש ופנסיה)?
A15: שיעור המשיכה הבטוח | B15: 0.038 | D15: =E2-E10-E12 -> 139200.64
D16: שכר בסיס נטו | E16: קרן השתלמות ופנסיה | F16: מניות ובונוסים נטו
D17: =55%*B13 -> 24750 | E17: =(20.833%)*B13+1571*2 -> 12516.85 | F17: =D15-D17-E17 -> 101933.79
E19: ברוטו בדולרים בשנה זה | F19: =F17*12*2/3.7 -> 661192.17
A20: הטבלה הזו - מראה טריידאוף בין עוצמת החיסכון לעוצמת התשואה (הריאלית)
A21: חסכון / תשואה | B21: 0.03 | C21: 0.04 | D21: 0.05 | E21: 0.06 | F21: 0.07 | G21: 0.08
A22: 0.1 | B22: =-FV(B$21,'תכנון פרישה (מינימום FU money)'!שנות_עבודה_שנותרו,$D$15*12*$A22)+('תכנון פרישה (מינימום FU money)'!חסכון_נוכחי_2023*(1+B$21)^'תכנון פרישה (מינימום FU money)'!שנות_עבודה_שנותרו) -> 872103.24 | C22: =-FV(C$21,'תכנון פרישה (מינימום FU money)'!שנות_עבודה_שנותרו,$D$15*12*$A22)+('תכנון פרישה (מינימום FU money)'!חסכון_נוכחי_2023*(1+C$21)^'תכנון פרישה (מינימום FU money)'!שנות_עבודה_שנותרו) -> 889593.5 | D22: =-FV(D$21,'תכנון פרישה (מינימום FU money)'!שנות_עבודה_שנותרו,$D$15*12*$A22)+('תכנון פרישה (מינימום FU money)'!חסכון_נוכחי_2023*(1+D$21)^'תכנון פרישה (מינימום FU money)'!שנות_עבודה_שנותרו) -> 907434.55 | E22: =-FV(E$21,'תכנון פרישה (מינימום FU money)'!שנות_עבודה_שנותרו,$D$15*12*$A22)+('תכנון פרישה (מינימום FU money)'!חסכון_נוכחי_2023*(1+E$21)^'תכנון פרישה (מינימום FU money)'!שנות_עבודה_שנותרו) -> 925631.86 | F22: =-FV(F$21,'תכנון פרישה (מינימום FU money)'!שנות_עבודה_שנותרו,$D$15*12*$A22)+('תכנון פרישה (מינימום FU money)'!חסכון_נוכחי_2023*(1+F$21)^'תכנון פרישה (מינימום FU money)'!שנות_עבודה_שנותרו) -> 944190.93 | G22: =-FV(G$21,'תכנון פרישה (מינימום FU money)'!שנות_עבודה_שנותרו,$D$15*12*$A22)+('תכנון פרישה (מינימום FU money)'!חסכון_נוכחי_2023*(1+G$21)^'תכנון פרישה (מינימום FU money)'!שנות_עבודה_שנותרו) -> 963117.32
A23: כמה נמשוך רק מהתשואה בגיל פרישה | B23: =B22*B$21/12 -> 2180.2581 | C23: =C22*C$21/12 -> 2965.3117 | D23: =D22*D$21/12 -> 3780.9773 | E23: =E22*E$21/12 -> 4628.1593 | F23: =F22*F$21/12 -> 5507.7805 | G23: =G22*G$21/12 -> 6420.7822
A24: ="כמה נמשוך כולל הקרן , מהפרישה ועד גיל "&$E$4&"" -> כמה נמשוך כולל הקרן , מהפרישה ועד גיל 60 | B24: =-PMT(B$21,'תכנון פרישה (מינימום FU money)'!גיל_הפנסיה-'תכנון פרישה (מינימום FU money)'!הגיל_שלנו_2023-'תכנון פרישה (מינימום FU money)'!שנות_עבודה_שנותרו,B22)/12 -> 3829.4787 | C24: =-PMT(C$21,'תכנון פרישה (מינימום FU money)'!גיל_הפנסיה-'תכנון פרישה (מינימום FU money)'!הגיל_שלנו_2023-'תכנון פרישה (מינימום FU money)'!שנות_עבודה_שנותרו,C22)/12 -> 4406.1197 | D24: =-PMT(D$21,'תכנון פרישה (מינימום FU money)'!גיל_הפנסיה-'תכנון פרישה (מינימום FU money)'!הגיל_שלנו_2023-'תכנון פרישה (מינימום FU money)'!שנות_עבודה_שנותרו,D22)/12 -> 5034.2276 | E24: =-PMT(E$21,'תכנון פרישה (מינימום FU money)'!גיל_הפנסיה-'תכנון פרישה (מינימום FU money)'!הגיל_שלנו_2023-'תכנון פרישה (מינימום FU money)'!שנות_עבודה_שנותרו,E22)/12 -> 5713.8672 | F24: =-PMT(F$21,'תכנון פרישה (מינימום FU money)'!גיל_הפנסיה-'תכנון פרישה (מינימום FU money)'!הגיל_שלנו_2023-'תכנון פרישה (מינימום FU money)'!שנות_עבודה_שנותרו,F22)/12 -> 6444.8584 | G24: =-PMT(G$21,'תכנון פרישה (מינימום FU money)'!גיל_הפנסיה-'תכנון פרישה (מינימום FU money)'!הגיל_שלנו_2023-'תכנון פרישה (מינימום FU money)'!שנות_עבודה_שנותרו,G22)/12 -> 7226.8509
A25: 0.15 | B25: =-FV(B$21,'תכנון פרישה (מינימום FU money)'!שנות_עבודה_שנותרו,$D$15*12*$A25)+('תכנון פרישה (מינימום FU money)'!חסכון_נוכחי_2023*(1+B$21)^'תכנון פרישה (מינימום FU money)'!שנות_עבודה_שנותרו) -> 1268175.5 | C25: =-FV(C$21,'תכנון פרישה (מינימום FU money)'!שנות_עבודה_שנותרו,$D$15*12*$A25)+('תכנון פרישה (מינימום FU money)'!חסכון_נוכחי_2023*(1+C$21)^'תכנון פרישה (מינימום FU money)'!שנות_עבודה_שנותרו) -> 1292634.3 | D25: =-FV(D$21,'תכנון פרישה (מינימום FU money)'!שנות_עבודה_שנותרו,$D$15*12*$A25)+('תכנון פרישה (מינימום FU money)'!חסכון_נוכחי_2023*(1+D$21)^'תכנון פרישה (מינימום FU money)'!שנות_עבודה_שנותרו) -> 1317558.5 | E25: =-FV(E$21,'תכנון פרישה (מינימום FU money)'!שנות_עבודה_שנותרו,$D$15*12*$A25)+('תכנון פרישה (מינימום FU money)'!חסכון_נוכחי_2023*(1+E$21)^'תכנון פרישה (מינימום FU money)'!שנות_עבודה_שנותרו) -> 1342954.8 | F25: =-FV(F$21,'תכנון פרישה (מינימום FU money)'!שנות_עבודה_שנותרו,$D$15*12*$A25)+('תכנון פרישה (מינימום FU money)'!חסכון_נוכחי_2023*(1+F$21)^'תכנון פרישה (מינימום FU money)'!שנות_עבודה_שנותרו) -> 1368830 | G25: =-FV(G$21,'תכנון פרישה (מינימום FU money)'!שנות_עבודה_שנותרו,$D$15*12*$A25)+('תכנון פרישה (מינימום FU money)'!חסכון_נוכחי_2023*(1+G$21)^'תכנון פרישה (מינימום FU money)'!שנות_עבודה_שנותרו) -> 1395190.8
A26: כמה נמשוך רק מהתשואה בגיל פרישה | B26: =B25*B$21/12 -> 3170.4388 | C26: =C25*C$21/12 -> 4308.7811 | D26: =D25*D$21/12 -> 5489.8272 | E26: =E25*E$21/12 -> 6714.7741 | F26: =F25*F$21/12 -> 7984.8415 | G26: =G25*G$21/12 -> 9301.2722
A27: ="כמה נמשוך כולל הקרן , מהפרישה ועד גיל "&$E$4&"" -> כמה נמשוך כולל הקרן , מהפרישה ועד גיל 60 | B27: =-PMT(B$21,'תכנון פרישה (מינימום FU money)'!גיל_הפנסיה-'תכנון פרישה (מינימום FU money)'!הגיל_שלנו_2023-'תכנון פרישה (מינימום FU money)'!שנות_עבודה_שנותרו,B25)/12 -> 5568.6654 | C27: =-PMT(C$21,'תכנון פרישה (מינימום FU money)'!גיל_הפנסיה-'תכנון פרישה (מינימום FU money)'!הגיל_שלנו_2023-'תכנון פרישה (מינימום FU money)'!שנות_עבודה_שנותרו,C25)/12 -> 6402.3642 | D27: =-PMT(D$21,'תכנון פרישה (מינימום FU money)'!גיל_הפנסיה-'תכנון פרישה (מינימום FU money)'!הגיל_שלנו_2023-'תכנון פרישה (מינימום FU money)'!שנות_עבודה_שנותרו,D25)/12 -> 7309.4963 | E27: =-PMT(E$21,'תכנון פרישה (מינימום FU money)'!גיל_הפנסיה-'תכנון פרישה (מינימום FU money)'!הגיל_שלנו_2023-'תכנון פרישה (מינימום FU money)'!שנות_עבודה_שנותרו,E25)/12 -> 8289.9754 | F27: =-PMT(F$21,'תכנון פרישה (מינימום FU money)'!גיל_הפנסיה-'תכנון פרישה (מינימום FU money)'!הגיל_שלנו_2023-'תכנון פרישה (מינימום FU money)'!שנות_עבודה_שנותרו,F25)/12 -> 9343.3595 | G27: =-PMT(G$21,'תכנון פרישה (מינימום FU money)'!גיל_הפנסיה-'תכנון פרישה (מינימום FU money)'!הגיל_שלנו_2023-'תכנון פרישה (מינימום FU money)'!שנות_עבודה_שנותרו,G25)/12 -> 10468.959
A28: 0.2 | B28: =-FV(B$21,'תכנון פרישה (מינימום FU money)'!שנות_עבודה_שנותרו,$D$15*12*$A28)+('תכנון פרישה (מינימום FU money)'!חסכון_נוכחי_2023*(1+B$21)^'תכנון פרישה (מינימום FU money)'!שנות_עבודה_שנותרו) -> 1664247.8 | C28: =-FV(C$21,'תכנון פרישה (מינימום FU money)'!שנות_עבודה_שנותרו,$D$15*12*$A28)+('תכנון פרישה (מינימום FU money)'!חסכון_נוכחי_2023*(1+C$21)^'תכנון פרישה (מינימום FU money)'!שנות_עבודה_שנותרו) -> 1695675.1 | D28: =-FV(D$21,'תכנון פרישה (מינימום FU money)'!שנות_עבודה_שנותרו,$D$15*12*$A28)+('תכנון פרישה (מינימום FU money)'!חסכון_נוכחי_2023*(1+D$21)^'תכנון פרישה (מינימום FU money)'!שנות_עבודה_שנותרו) -> 1727682.5 | E28: =-FV(E$21,'תכנון פרישה (מינימום FU money)'!שנות_עבודה_שנותרו,$D$15*12*$A28)+('תכנון פרישה (מינימום FU money)'!חסכון_נוכחי_2023*(1+E$21)^'תכנון פרישה (מינימום FU money)'!שנות_עבודה_שנותרו) -> 1760277.8 | F28: =-FV(F$21,'תכנון פרישה (מינימום FU money)'!שנות_עבודה_שנותרו,$D$15*12*$A28)+('תכנון פרישה (מינימום FU money)'!חסכון_נוכחי_2023*(1+F$21)^'תכנון פרישה (מינימום FU money)'!שנות_עבודה_שנותרו) -> 1793469 | G28: =-FV(G$21,'תכנון פרישה (מינימום FU money)'!שנות_עבודה_שנותרו,$D$15*12*$A28)+('תכנון פרישה (מינימום FU money)'!חסכון_נוכחי_2023*(1+G$21)^'תכנון פרישה (מינימום FU money)'!שנות_עבודה_שנותרו) -> 1827264.3
A29: כמה נמשוך רק מהתשואה בגיל פרישה | B29: =B28*B$21/12 -> 4160.6195 | C29: =C28*C$21/12 -> 5652.2505 | D29: =D28*D$21/12 -> 7198.677 | E29: =E28*E$21/12 -> 8801.3888 | F29: =F28*F$21/12 -> 10461.903 | G29: =G28*G$21/12 -> 12181.762
A30: ="כמה נמשוך כולל הקרן , מהפרישה ועד גיל "&$E$4&"" -> כמה נמשוך כולל הקרן , מהפרישה ועד גיל 60 | B30: =-PMT(B$21,'תכנון פרישה (מינימום FU money)'!גיל_הפנסיה-'תכנון פרישה (מינימום FU money)'!הגיל_שלנו_2023-'תכנון פרישה (מינימום FU money)'!שנות_עבודה_שנותרו,B28)/12 -> 7307.8522 | C30: =-PMT(C$21,'תכנון פרישה (מינימום FU money)'!גיל_הפנסיה-'תכנון פרישה (מינימום FU money)'!הגיל_שלנו_2023-'תכנון פרישה (מינימום FU money)'!שנות_עבודה_שנותרו,C28)/12 -> 8398.6087 | D30: =-PMT(D$21,'תכנון פרישה (מינימום FU money)'!גיל_הפנסיה-'תכנון פרישה (מינימום FU money)'!הגיל_שלנו_2023-'תכנון פרישה (מינימום FU money)'!שנות_עבודה_שנותרו,D28)/12 -> 9584.7649 | E30: =-PMT(E$21,'תכנון פרישה (מינימום FU money)'!גיל_הפנסיה-'תכנון פרישה (מינימום FU money)'!הגיל_שלנו_2023-'תכנון פרישה (מינימום FU money)'!שנות_עבודה_שנותרו,E28)/12 -> 10866.084 | F30: =-PMT(F$21,'תכנון פרישה (מינימום FU money)'!גיל_הפנסיה-'תכנון פרישה (מינימום FU money)'!הגיל_שלנו_2023-'תכנון פרישה (מינימום FU money)'!שנות_עבודה_שנותרו,F28)/12 -> 12241.861 | G30: =-PMT(G$21,'תכנון פרישה (מינימום FU money)'!גיל_הפנסיה-'תכנון פרישה (מינימום FU money)'!הגיל_שלנו_2023-'תכנון פרישה (מינימום FU money)'!שנות_עבודה_שנותרו,G28)/12 -> 13711.068
A31: 0.25 | B31: =-FV(B$21,'תכנון פרישה (מינימום FU money)'!שנות_עבודה_שנותרו,$D$15*12*$A31)+('תכנון פרישה (מינימום FU money)'!חסכון_נוכחי_2023*(1+B$21)^'תכנון פרישה (מינימום FU money)'!שנות_עבודה_שנותרו) -> 2060320.1 | C31: =-FV(C$21,'תכנון פרישה (מינימום FU money)'!שנות_עבודה_שנותרו,$D$15*12*$A31)+('תכנון פרישה (מינימום FU money)'!חסכון_נוכחי_2023*(1+C$21)^'תכנון פרישה (מינימום FU money)'!שנות_עבודה_שנותרו) -> 2098716 | D31: =-FV(D$21,'תכנון פרישה (מינימום FU money)'!שנות_עבודה_שנותרו,$D$15*12*$A31)+('תכנון פרישה (מינימום FU money)'!חסכון_נוכחי_2023*(1+D$21)^'תכנון פרישה (מינימום FU money)'!שנות_עבודה_שנותרו) -> 2137806.4 | E31: =-FV(E$21,'תכנון פרישה (מינימום FU money)'!שנות_עבודה_שנותרו,$D$15*12*$A31)+('תכנון פרישה (מינימום FU money)'!חסכון_נוכחי_2023*(1+E$21)^'תכנון פרישה (מינימום FU money)'!שנות_עבודה_שנותרו) -> 2177600.7 | F31: =-FV(F$21,'תכנון פרישה (מינימום FU money)'!שנות_עבודה_שנותרו,$D$15*12*$A31)+('תכנון פרישה (מינימום FU money)'!חסכון_נוכחי_2023*(1+F$21)^'תכנון פרישה (מינימום FU money)'!שנות_עבודה_שנותרו) -> 2218108.1 | G31: =-FV(G$21,'תכנון פרישה (מינימום FU money)'!שנות_עבודה_שנותרו,$D$15*12*$A31)+('תכנון פרישה (מינימום FU money)'!חסכון_נוכחי_2023*(1+G$21)^'תכנון פרישה (מינימום FU money)'!שנות_עבודה_שנותרו) -> 2259337.8
A32: כמה נמשוך רק מהתשואה בגיל פרישה | B32: =B31*B$21/12 -> 5150.8002 | C32: =C31*C$21/12 -> 6995.7199 | D32: =D31*D$21/12 -> 8907.5268 | E32: =E31*E$21/12 -> 10888.004 | F32: =F31*F$21/12 -> 12938.964 | G32: =G31*G$21/12 -> 15062.252
A33: ="כמה נמשוך כולל הקרן , מהפרישה ועד גיל "&$E$4&"" -> כמה נמשוך כולל הקרן , מהפרישה ועד גיל 60 | B33: =-PMT(B$21,'תכנון פרישה (מינימום FU money)'!גיל_הפנסיה-'תכנון פרישה (מינימום FU money)'!הגיל_שלנו_2023-'תכנון פרישה (מינימום FU money)'!שנות_עבודה_שנותרו,B31)/12 -> 9047.0389 | C33: =-PMT(C$21,'תכנון פרישה (מינימום FU money)'!גיל_הפנסיה-'תכנון פרישה (מינימום FU money)'!הגיל_שלנו_2023-'תכנון פרישה (מינימום FU money)'!שנות_עבודה_שנותרו,C31)/12 -> 10394.853 | D33: =-PMT(D$21,'תכנון פרישה (מינימום FU money)'!גיל_הפנסיה-'תכנון פרישה (מינימום FU money)'!הגיל_שלנו_2023-'תכנון פרישה (מינימום FU money)'!שנות_עבודה_שנותרו,D31)/12 -> 11860.034 | E33: =-PMT(E$21,'תכנון פרישה (מינימום FU money)'!גיל_הפנסיה-'תכנון פרישה (מינימום FU money)'!הגיל_שלנו_2023-'תכנון פרישה (מינימום FU money)'!שנות_עבודה_שנותרו,E31)/12 -> 13442.192 | F33: =-PMT(F$21,'תכנון פרישה (מינימום FU money)'!גיל_הפנסיה-'תכנון פרישה (מינימום FU money)'!הגיל_שלנו_2023-'תכנון פרישה (מינימום FU money)'!שנות_עבודה_שנותרו,F31)/12 -> 15140.362 | G33: =-PMT(G$21,'תכנון פרישה (מינימום FU money)'!גיל_הפנסיה-'תכנון פרישה (מינימום FU money)'!הגיל_שלנו_2023-'תכנון פרישה (מינימום FU money)'!שנות_עבודה_שנותרו,G31)/12 -> 16953.176
A34: 0.3 | B34: =-FV(B$21,'תכנון פרישה (מינימום FU money)'!שנות_עבודה_שנותרו,$D$15*12*$A34)+('תכנון פרישה (מינימום FU money)'!חסכון_נוכחי_2023*(1+B$21)^'תכנון פרישה (מינימום FU money)'!שנות_עבודה_שנותרו) -> 2456392.4 | C34: =-FV(C$21,'תכנון פרישה (מינימום FU money)'!שנות_עבודה_שנותרו,$D$15*12*$A34)+('תכנון פרישה (מינימום FU money)'!חסכון_נוכחי_2023*(1+C$21)^'תכנון פרישה (מינימום FU money)'!שנות_עבודה_שנותרו) -> 2501756.8 | D34: =-FV(D$21,'תכנון פרישה (מינימום FU money)'!שנות_עבודה_שנותרו,$D$15*12*$A34)+('תכנון פרישה (מינימום FU money)'!חסכון_נוכחי_2023*(1+D$21)^'תכנון פרישה (מינימום FU money)'!שנות_עבודה_שנותרו) -> 2547930.4 | E34: =-FV(E$21,'תכנון פרישה (מינימום FU money)'!שנות_עבודה_שנותרו,$D$15*12*$A34)+('תכנון פרישה (מינימום FU money)'!חסכון_נוכחי_2023*(1+E$21)^'תכנון פרישה (מינימום FU money)'!שנות_עבודה_שנותרו) -> 2594923.7 | F34: =-FV(F$21,'תכנון פרישה (מינימום FU money)'!שנות_עבודה_שנותרו,$D$15*12*$A34)+('תכנון פרישה (מינימום FU money)'!חסכון_נוכחי_2023*(1+F$21)^'תכנון פרישה (מינימום FU money)'!שנות_עבודה_שנותרו) -> 2642747.1 | G34: =-FV(G$21,'תכנון פרישה (מינימום FU money)'!שנות_עבודה_שנותרו,$D$15*12*$A34)+('תכנון פרישה (מינימום FU money)'!חסכון_נוכחי_2023*(1+G$21)^'תכנון פרישה (מינימום FU money)'!שנות_עבודה_שנותרו) -> 2691411.3
A35: כמה נמשוך רק מהתשואה בגיל פרישה | B35: =B34*B$21/12 -> 6140.9809 | C35: =C34*C$21/12 -> 8339.1893 | D35: =D34*D$21/12 -> 10616.377 | E35: =E34*E$21/12 -> 12974.618 | F35: =F34*F$21/12 -> 15416.025 | G35: =G34*G$21/12 -> 17942.742
A36: ="כמה נמשוך כולל הקרן , מהפרישה ועד גיל "&$E$4&"" -> כמה נמשוך כולל הקרן , מהפרישה ועד גיל 60 | B36: =-PMT(B$21,'תכנון פרישה (מינימום FU money)'!גיל_הפנסיה-'תכנון פרישה (מינימום FU money)'!הגיל_שלנו_2023-'תכנון פרישה (מינימום FU money)'!שנות_עבודה_שנותרו,B34)/12 -> 10786.226 | C36: =-PMT(C$21,'תכנון פרישה (מינימום FU money)'!גיל_הפנסיה-'תכנון פרישה (מינימום FU money)'!הגיל_שלנו_2023-'תכנון פרישה (מינימום FU money)'!שנות_עבודה_שנותרו,C34)/12 -> 12391.098 | D36: =-PMT(D$21,'תכנון פרישה (מינימום FU money)'!גיל_הפנסיה-'תכנון פרישה (מינימום FU money)'!הגיל_שלנו_2023-'תכנון פרישה (מינימום FU money)'!שנות_עבודה_שנותרו,D34)/12 -> 14135.302 | E36: =-PMT(E$21,'תכנון פרישה (מינימום FU money)'!גיל_הפנסיה-'תכנון פרישה (מינימום FU money)'!הגיל_שלנו_2023-'תכנון פרישה (מינימום FU money)'!שנות_עבודה_שנותרו,E34)/12 -> 16018.3 | F36: =-PMT(F$21,'תכנון פרישה (מינימום FU money)'!גיל_הפנסיה-'תכנון פרישה (מינימום FU money)'!הגיל_שלנו_2023-'תכנון פרישה (מינימום FU money)'!שנות_עבודה_שנותרו,F34)/12 -> 18038.863 | G36: =-PMT(G$21,'תכנון פרישה (מינימום FU money)'!גיל_הפנסיה-'תכנון פרישה (מינימום FU money)'!הגיל_שלנו_2023-'תכנון פרישה (מינימום FU money)'!שנות_עבודה_שנותרו,G34)/12 -> 20195.285
A37: 0.35 | B37: =-FV(B$21,'תכנון פרישה (מינימום FU money)'!שנות_עבודה_שנותרו,$D$15*12*$A37)+('תכנון פרישה (מינימום FU money)'!חסכון_נוכחי_2023*(1+B$21)^'תכנון פרישה (מינימום FU money)'!שנות_עבודה_שנותרו) -> 2852464.7 | C37: =-FV(C$21,'תכנון פרישה (מינימום FU money)'!שנות_עבודה_שנותרו,$D$15*12*$A37)+('תכנון פרישה (מינימום FU money)'!חסכון_נוכחי_2023*(1+C$21)^'תכנון פרישה (מינימום FU money)'!שנות_עבודה_שנותרו) -> 2904797.6 | D37: =-FV(D$21,'תכנון פרישה (מינימום FU money)'!שנות_עבודה_שנותרו,$D$15*12*$A37)+('תכנון פרישה (מינימום FU money)'!חסכון_נוכחי_2023*(1+D$21)^'תכנון פרישה (מינימום FU money)'!שנות_עבודה_שנותרו) -> 2958054.4 | E37: =-FV(E$21,'תכנון פרישה (מינימום FU money)'!שנות_עבודה_שנותרו,$D$15*12*$A37)+('תכנון פרישה (מינימום FU money)'!חסכון_נוכחי_2023*(1+E$21)^'תכנון פרישה (מינימום FU money)'!שנות_עבודה_שנותרו) -> 3012246.6 | F37: =-FV(F$21,'תכנון פרישה (מינימום FU money)'!שנות_עבודה_שנותרו,$D$15*12*$A37)+('תכנון פרישה (מינימום FU money)'!חסכון_נוכחי_2023*(1+F$21)^'תכנון פרישה (מינימום FU money)'!שנות_עבודה_שנותרו) -> 3067386.1 | G37: =-FV(G$21,'תכנון פרישה (מינימום FU money)'!שנות_עבודה_שנותרו,$D$15*12*$A37)+('תכנון פרישה (מינימום FU money)'!חסכון_נוכחי_2023*(1+G$21)^'תכנון פרישה (מינימום FU money)'!שנות_עבודה_שנותרו) -> 3123484.9
A38: כמה נמשוך רק מהתשואה בגיל פרישה | B38: =B37*B$21/12 -> 7131.1616 | C38: =C37*C$21/12 -> 9682.6588 | D38: =D37*D$21/12 -> 12325.227 | E38: =E37*E$21/12 -> 15061.233 | F38: =F37*F$21/12 -> 17893.086 | G38: =G37*G$21/12 -> 20823.232
A39: ="כמה נמשוך כולל הקרן , מהפרישה ועד גיל "&$E$4&"" -> כמה נמשוך כולל הקרן , מהפרישה ועד גיל 60 | B39: =-PMT(B$21,'תכנון פרישה (מינימום FU money)'!גיל_הפנסיה-'תכנון פרישה (מינימום FU money)'!הגיל_שלנו_2023-'תכנון פרישה (מינימום FU money)'!שנות_עבודה_שנותרו,B37)/12 -> 12525.412 | C39: =-PMT(C$21,'תכנון פרישה (מינימום FU money)'!גיל_הפנסיה-'תכנון פרישה (מינימום FU money)'!הגיל_שלנו_2023-'תכנון פרישה (מינימום FU money)'!שנות_עבודה_שנותרו,C37)/12 -> 14387.342 | D39: =-PMT(D$21,'תכנון פרישה (מינימום FU money)'!גיל_הפנסיה-'תכנון פרישה (מינימום FU money)'!הגיל_שלנו_2023-'תכנון פרישה (מינימום FU money)'!שנות_עבודה_שנותרו,D37)/12 -> 16410.571 | E39: =-PMT(E$21,'תכנון פרישה (מינימום FU money)'!גיל_הפנסיה-'תכנון פרישה (מינימום FU money)'!הגיל_שלנו_2023-'תכנון פרישה (מינימום FU money)'!שנות_עבודה_שנותרו,E37)/12 -> 18594.408 | F39: =-PMT(F$21,'תכנון פרישה (מינימום FU money)'!גיל_הפנסיה-'תכנון פרישה (מינימום FU money)'!הגיל_שלנו_2023-'תכנון פרישה (מינימום FU money)'!שנות_עבודה_שנותרו,F37)/12 -> 20937.364 | G39: =-PMT(G$21,'תכנון פרישה (מינימום FU money)'!גיל_הפנסיה-'תכנון פרישה (מינימום FU money)'!הגיל_שלנו_2023-'תכנון פרישה (מינימום FU money)'!שנות_עבודה_שנותרו,G37)/12 -> 23437.393
A40: 0.4 | B40: =-FV(B$21,'תכנון פרישה (מינימום FU money)'!שנות_עבודה_שנותרו,$D$15*12*$A40)+('תכנון פרישה (מינימום FU money)'!חסכון_נוכחי_2023*(1+B$21)^'תכנון פרישה (מינימום FU money)'!שנות_עבודה_שנותרו) -> 3248536.9 | C40: =-FV(C$21,'תכנון פרישה (מינימום FU money)'!שנות_עבודה_שנותרו,$D$15*12*$A40)+('תכנון פרישה (מינימום FU money)'!חסכון_נוכחי_2023*(1+C$21)^'תכנון פרישה (מינימום FU money)'!שנות_עבודה_שנותרו) -> 3307838.5 | D40: =-FV(D$21,'תכנון פרישה (מינימום FU money)'!שנות_עבודה_שנותרו,$D$15*12*$A40)+('תכנון פרישה (מינימום FU money)'!חסכון_נוכחי_2023*(1+D$21)^'תכנון פרישה (מינימום FU money)'!שנות_עבודה_שנותרו) -> 3368178.3 | E40: =-FV(E$21,'תכנון פרישה (מינימום FU money)'!שנות_עבודה_שנותרו,$D$15*12*$A40)+('תכנון פרישה (מינימום FU money)'!חסכון_נוכחי_2023*(1+E$21)^'תכנון פרישה (מינימום FU money)'!שנות_עבודה_שנותרו) -> 3429569.5 | F40: =-FV(F$21,'תכנון פרישה (מינימום FU money)'!שנות_עבודה_שנותרו,$D$15*12*$A40)+('תכנון פרישה (מינימום FU money)'!חסכון_נוכחי_2023*(1+F$21)^'תכנון פרישה (מינימום FU money)'!שנות_עבודה_שנותרו) -> 3492025.2 | G40: =-FV(G$21,'תכנון פרישה (מינימום FU money)'!שנות_עבודה_שנותרו,$D$15*12*$A40)+('תכנון פרישה (מינימום FU money)'!חסכון_נוכחי_2023*(1+G$21)^'תכנון פרישה (מינימום FU money)'!שנות_עבודה_שנותרו) -> 3555558.4
A41: כמה נמשוך רק מהתשואה בגיל פרישה | B41: =B40*B$21/12 -> 8121.3423 | C41: =C40*C$21/12 -> 11026.128 | D41: =D40*D$21/12 -> 14034.076 | E41: =E40*E$21/12 -> 17147.848 | F41: =F40*F$21/12 -> 20370.147 | G41: =G40*G$21/12 -> 23703.722
...

Sheet תכנון פרישה (מקסימום תשואה)
I1: מהפרישה המוקדמת ועד גיל הפרישה (הפנסיה) | O1: בפנסיה
A2: שנות עבודה עד הפרישה | B2: 8 | D2: הכנסה חודשית ברוטו מפרישה ועד גיל פנסיה (לרמת החיים שהתרגלנו) | E2: ='תכנון פרישה'!E2 -> 30000 | K2: חיסכון חודשי בעת העבודה | L2: מצב בעת הפרישה | Q2: מצב בעת היציאה לפנסיה
J3: קופות גמל | K3: =(8.33%+6%+6.5%)*'תכנון פרישה (מקסימום תשואה)'!השכר_הסוציאלי_2023-'תכנון פרישה (מקסימום תשואה)'!תקרת_הפקדה_לפנסיה_בשנת_2023 -> 4507.5 | L3: =fv($B$4,$B$2,-K3*12)+'תכנון פרישה (מקסימום תשואה)'!קופת_גמל*(1+$B$4)^$B$2 -> 554952.72 | P3: קופות גמל | Q3: =L3*(1+'תכנון פרישה (מקסימום תשואה)'!תשואה_ריאלית)^('תכנון פרישה (מקסימום תשואה)'!גיל_הפנסיה-'תכנון פרישה (מקסימום תשואה)'!שנות_עבודה_שנותרו-'תכנון פרישה (מקסימום תשואה)'!הגיל_שלנו_2023) -> 3011968.5
A4: תשואה ריאלית על השקעות ונכסים | B4: 0.07 | D4: גיל למשיכת כספים סוציאליים (לפחות 60) | E4: 60 | J4: קרנות פנסיה | K4: 4866 | L4: =fv($B$4,$B$2,-K4*12)+'תכנון פרישה (מקסימום תשואה)'!קרן_פנסיה*(1+$B$4)^$B$2 -> 856818.32 | P4: קרנות פנסיה | Q4: =L4*(1+'תכנון פרישה (מקסימום תשואה)'!תשואה_ריאלית)^('תכנון פרישה (מקסימום תשואה)'!גיל_הפנסיה-'תכנון פרישה (מקסימום תשואה)'!שנות_עבודה_שנותרו-'תכנון פרישה (מקסימום תשואה)'!הגיל_שלנו_2023) -> 4650323.7
A5: קרנות השתלמות | B5: ='תכנון פרישה'!B5 -> 70000 | J5: קרן השתלמות | K5: =1571*2 -> 3142 | L5: =fv($B$4,$B$2,-K5*12)+B5*(1+$B$4)^$B$2 -> 507108.63
A6: הון עצמי מושקע | B6: ='תכנון פרישה'!B6 -> 100000 | J6: הון עצמי מושקע | K6: =-E12-sum(K3:K5) -> 59966.927 | L6: =fv($B$4,$B$2,-K6*12)+B6*(1+$B$4)^$B$2 -> 7554804.5 | P6: פנסיה ברוטו | Q6: =SUM(Q3:Q4)/(202+4*(67-E4)) -> 33314.314
A7: קרנות פנסיה | B7: ='תכנון פרישה'!B7 -> 150000
A8: קופת גמל \ ביטוחי מנהלים | B8: ='תכנון פרישה'!B8 | J8: הון עצמי לשימושנו | K8: =L5+L6 -> 8061913.2
A9: ריבית משכנתא ממוצעת | B9: ='תכנון פרישה'!B9 -> 0.045 | E9: מחושב | F9: באחוזים מהשכר | J9: למשך תקופה של | K9: =E4-B2-B14 -> 25 | L9: שנים
A10: יתרת משכנתא | B10: ='תכנון פרישה'!B10 -> 900000 | D10: תשלום חודשי לבית | E10: =PMT(B9,$B$2,B10)/12 -> -11370.724 | F10: =-E10/$D$15 -> 0.099871843 | J10: בשיעור משיכה של | K10: =E2*12/K8 -> 0.044654413 | L10: בשנה
A11: סכום שיידרש בגיל הפרישה (כילוי מלא ללא השקעה) | B11: =E2*12*('תכנון פרישה (מקסימום תשואה)'!גיל_הפנסיה-'תכנון פרישה (מקסימום תשואה)'!הגיל_שלנו_2023-'תכנון פרישה (מקסימום תשואה)'!שנות_עבודה_שנותרו) -> 9000000 | D11: תשלום חודשי להשקעות | E11: =PMT($B$4,$B$2, ,B11-($B$5*(1+$B$4)^$B$2))/12 -> -72123.927 | F11: =-E11/$D$15 -> 0.63348204
A12: סכום שיידרש בגיל הפרישה (ללא כילוי) | B12: =E2*12/'תכנון פרישה (מקסימום תשואה)'!שיעור_משיכה_בטוח -> 9473684.2 | D12: תשלום חודשי להשקעות | E12: =PMT($B$4,$B$2, ,B12-(($B$5+$B$6+$B$7+$B$8)*(1+$B$4)^$B$2))/12 -> -72482.427 | F12: =-E12/$D$15 -> 0.63663084
A13: השכר הסוציאלי (ברוטו) למשק בית בממוצע לשנים האלו | B13: ='תכנון פרישה'!B13 -> 45000
A14: הגיל היום | B14: ='תכנון פרישה'!B14 -> 27 | D14: אז כמה נטו צריך בחודש בשביל זה (כולל קה"ש ופנסיה)?
A15: שיעור המשיכה הבטוח | B15: 0.038 | D15: =E2-E10-E12 -> 113853.15
D16: שכר בסיס נטו | E16: קרן השתלמות ופנסיה | F16: מניות ובונוסים נטו
D17: =55%*B13 -> 24750 | E17: =(20.833%)*B13+1571*2 -> 12516.85 | F17: =D15-D17-E17 -> 76586.301
E19: ברוטו בדולרים בשנה זה | F19: =F17*12*2/3.7 -> 496776
A20: הטבלה הזו - מראה טריידאוף בין עוצמת החיסכון לעוצמת התשואה (הריאלית)
A21: חסכון / תשואה | B21: 0.03 | C21: 0.04 | D21: 0.05 | E21: 0.06 | F21: 0.07 | G21: 0.08
A22: 0.1 | B22: =-FV(B$21,'תכנון פרישה (מקסימום תשואה)'!שנות_עבודה_שנותרו,$D$15*12*$A22)+('תכנון פרישה (מקסימום תשואה)'!חסכון_נוכחי_2023*(1+B$21)^'תכנון פרישה (מקסימום תשואה)'!שנות_עבודה_שנותרו) -> 1303578.5 | C22: =-FV(C$21,'תכנון פרישה (מקסימום תשואה)'!שנות_עבודה_שנותרו,$D$15*12*$A22)+('תכנון פרישה (מקסימום תשואה)'!חסכון_נוכחי_2023*(1+C$21)^'תכנון פרישה (מקסימום תשואה)'!שנות_עבודה_שנותרו) -> 1354682.3 | D22: =-FV(D$21,'תכנון פרישה (מקסימום תשואה)'!שנות_עבודה_שנותרו,$D$15*12*$A22)+('תכנון פרישה (מקסימום תשואה)'!חסכון_נוכחי_2023*(1+D$21)^'תכנון פרישה (מקסימום תשואה)'!שנות_עבודה_שנותרו) -> 1408057.2 | E22: =-FV(E$21,'תכנון פרישה (מקסימום תשואה)'!שנות_עבודה_שנותרו,$D$15*12*$A22)+('תכנון פרישה (מקסימום תשואה)'!חסכון_נוכחי_2023*(1+E$21)^'תכנון פרישה (מקסימום תשואה)'!שנות_עבודה_שנותרו) -> 1463798.9 | F22: =-FV(F$21,'תכנון פרישה (מקסימום תשואה)'!שנות_עבודה_שנותרו,$D$15*12*$A22)+('תכנון פרישה (מקסימום תשואה)'!חסכון_נוכחי_2023*(1+F$21)^'תכנון פרישה (מקסימום תשואה)'!שנות_עבודה_שנותרו) -> 1522006 | G22: =-FV(G$21,'תכנון פרישה (מקסימום תשואה)'!שנות_עבודה_שנותרו,$D$15*12*$A22)+('תכנון פרישה (מקסימום תשואה)'!חסכון_נוכחי_2023*(1+G$21)^'תכנון פרישה (מקסימום תשואה)'!שנות_עבודה_שנותרו) -> 1582781.4
A23: כמה נמשוך רק מהתשואה בגיל פרישה | B23: =B22*B$21/12 -> 3258.9462 | C23: =C22*C$21/12 -> 4515.6075 | D23: =D22*D$21/12 -> 5866.9052 | E23: =E22*E$21/12 -> 7318.9942 | F23: =F22*F$21/12 -> 8878.3686 | G23: =G22*G$21/12 -> 10551.876
A24: ="כמה נמשוך כולל הקרן , מהפרישה ועד גיל "&$E$4&"" -> כמה נמשוך כולל הקרן , מהפרישה ועד גיל 60 | B24: =-PMT(B$21,'תכנון פרישה (מקסימום תשואה)'!גיל_הפנסיה-'תכנון פרישה (מקסימום תשואה)'!הגיל_שלנו_2023-'תכנון פרישה (מקסימום תשואה)'!שנות_עבודה_שנותרו,B22)/12 -> 6238.478 | C24: =-PMT(C$21,'תכנון פרישה (מקסימום תשואה)'!גיל_הפנסיה-'תכנון פרישה (מקסימום תשואה)'!הגיל_שלנו_2023-'תכנון פרישה (מקסימום תשואה)'!שנות_עבודה_שנותרו,C22)/12 -> 7226.3225 | D24: =-PMT(D$21,'תכנון פרישה (מקסימום תשואה)'!גיל_הפנסיה-'תכנון פרישה (מקסימום תשואה)'!הגיל_שלנו_2023-'תכנון פרישה (מקסימום תשואה)'!שנות_עבודה_שנותרו,D22)/12 -> 8325.4268 | E24: =-PMT(E$21,'תכנון פרישה (מקסימום תשואה)'!גיל_הפנסיה-'תכנון פרישה (מקסימום תשואה)'!הגיל_שלנו_2023-'תכנון פרישה (מקסימום תשואה)'!שנות_עבודה_שנותרו,E22)/12 -> 9542.3483 | F24: =-PMT(F$21,'תכנון פרישה (מקסימום תשואה)'!גיל_הפנסיה-'תכנון פרישה (מקסימום תשואה)'!הגיל_שלנו_2023-'תכנון פרישה (מקסימום תשואה)'!שנות_עבודה_שנותרו,F22)/12 -> 10883.677 | G24: =-PMT(G$21,'תכנון פרישה (מקסימום תשואה)'!גיל_הפנסיה-'תכנון פרישה (מקסימום תשואה)'!הגיל_שלנו_2023-'תכנון פרישה (מקסימום תשואה)'!שנות_עבודה_שנותרו,G22)/12 -> 12356.086
A25: 0.15 | B25: =-FV(B$21,'תכנון פרישה (מקסימום תשואה)'!שנות_עבודה_שנותרו,$D$15*12*$A25)+('תכנון פרישה (מקסימום תשואה)'!חסכון_נוכחי_2023*(1+B$21)^'תכנון פרישה (מקסימום תשואה)'!שנות_עבודה_שנותרו) -> 1911030.8 | C25: =-FV(C$21,'תכנון פרישה (מקסימום תשואה)'!שנות_עבודה_שנותרו,$D$15*12*$A25)+('תכנון פרישה (מקסימום תשואה)'!חסכון_נוכחי_2023*(1+C$21)^'תכנון פרישה (מקסימום תשואה)'!שנות_עבודה_שנותרו) -> 1984123.5 | D25: =-FV(D$21,'תכנון פרישה (מקסימום תשואה)'!שנות_עבודה_שנותרו,$D$15*12*$A25)+('תכנון פרישה (מקסימום תשואה)'!חסכון_נוכחי_2023*(1+D$21)^'תכנון פרישה (מקסימום תשואה)'!שנות_עבודה_שנותרו) -> 2060374.9 | E25: =-FV(E$21,'תכנון פרישה (מקסימום תשואה)'!שנות_עבודה_שנותרו,$D$15*12*$A25)+('תכנון פרישה (מקסימום תשואה)'!חסכון_נוכחי_2023*(1+E$21)^'תכנון פרישה (מקסימום תשואה)'!שנות_עבודה_שנותרו) -> 2139913.6 | F25: =-FV(F$21,'תכנון פרישה (מקסימום תשואה)'!שנות_עבודה_שנותרו,$D$15*12*$A25)+('תכנון פרישה (מקסימום תשואה)'!חסכון_נוכחי_2023*(1+F$21)^'תכנון פרישה (מקסימום תשואה)'!שנות_עבודה_שנותרו) -> 2222872.6 | G25: =-FV(G$21,'תכנון פרישה (מקסימום תשואה)'!שנות_עבודה_שנותרו,$D$15*12*$A25)+('תכנון פרישה (מקסימום תשואה)'!חסכון_נוכחי_2023*(1+G$21)^'תכנון פרישה (מקסימום תשואה)'!שנות_עבודה_שנותרו) -> 2309389.5
A26: כמה נמשוך רק מהתשואה בגיל פרישה | B26: =B25*B$21/12 -> 4777.5769 | C26: =C25*C$21/12 -> 6613.7449 | D26: =D25*D$21/12 -> 8584.8955 | E26: =E25*E$21/12 -> 10699.568 | F26: =F25*F$21/12 -> 12966.757 | G26: =G25*G$21/12 -> 15395.93
A27: ="כמה נמשוך כולל הקרן , מהפרישה ועד גיל "&$E$4&"" -> כמה נמשוך כולל הקרן , מהפרישה ועד גיל 60 | B27: =-PMT(B$21,'תכנון פרישה (מקסימום תשואה)'!גיל_הפנסיה-'תכנון פרישה (מקסימום תשואה)'!הגיל_שלנו_2023-'תכנון פרישה (מקסימום תשואה)'!שנות_עבודה_שנותרו,B25)/12 -> 9145.5357 | C27: =-PMT(C$21,'תכנון פרישה (מקסימום תשואה)'!גיל_הפנסיה-'תכנון פרישה (מקסימום תשואה)'!הגיל_שלנו_2023-'תכנון פרישה (מקסימום תשואה)'!שנות_עבודה_שנותרו,C25)/12 -> 10583.97 | D27: =-PMT(D$21,'תכנון פרישה (מקסימום תשואה)'!גיל_הפנסיה-'תכנון פרישה (מקסימום תשואה)'!הגיל_שלנו_2023-'תכנון פרישה (מקסימום תשואה)'!שנות_עבודה_שנותרו,D25)/12 -> 12182.389 | E27: =-PMT(E$21,'תכנון פרישה (מקסימום תשואה)'!גיל_הפנסיה-'תכנון פרישה (מקסימום תשואה)'!הגיל_שלנו_2023-'תכנון פרישה (מקסימום תשואה)'!שנות_עבודה_שנותרו,E25)/12 -> 13949.868 | F27: =-PMT(F$21,'תכנון פרישה (מקסימום תשואה)'!גיל_הפנסיה-'תכנון פרישה (מקסימום תשואה)'!הגיל_שלנו_2023-'תכנון פרישה (מקסימום תשואה)'!שנות_עבודה_שנותרו,F25)/12 -> 15895.487 | G27: =-PMT(G$21,'תכנון פרישה (מקסימום תשואה)'!גיל_הפנסיה-'תכנון פרישה (מקסימום תשואה)'!הגיל_שלנו_2023-'תכנון פרישה (מקסימום תשואה)'!שנות_עבודה_שנותרו,G25)/12 -> 18028.399
A28: 0.2 | B28: =-FV(B$21,'תכנון פרישה (מקסימום תשואה)'!שנות_עבודה_שנותרו,$D$15*12*$A28)+('תכנון פרישה (מקסימום תשואה)'!חסכון_נוכחי_2023*(1+B$21)^'תכנון פרישה (מקסימום תשואה)'!שנות_עבודה_שנותרו) -> 2518483 | C28: =-FV(C$21,'תכנון פרישה (מקסימום תשואה)'!שנות_עבודה_שנותרו,$D$15*12*$A28)+('תכנון פרישה (מקסימום תשואה)'!חסכון_נוכחי_2023*(1+C$21)^'תכנון פרישה (מקסימום תשואה)'!שנות_עבודה_שנותרו) -> 2613564.7 | D28: =-FV(D$21,'תכנון פרישה (מקסימום תשואה)'!שנות_עבודה_שנותרו,$D$15*12*$A28)+('תכנון פרישה (מקסימום תשואה)'!חסכון_נוכחי_2023*(1+D$21)^'תכנון פרישה (מקסימום תשואה)'!שנות_עבודה_שנותרו) -> 2712692.6 | E28: =-FV(E$21,'תכנון פרישה (מקסימום תשואה)'!שנות_עבודה_שנותרו,$D$15*12*$A28)+('תכנון פרישה (מקסימום תשואה)'!חסכון_נוכחי_2023*(1+E$21)^'תכנון פרישה (מקסימום תשואה)'!שנות_עבודה_שנותרו) -> 2816028.3 | F28: =-FV(F$21,'תכנון פרישה (מקסימום תשואה)'!שנות_עבודה_שנותרו,$D$15*12*$A28)+('תכנון פרישה (מקסימום תשואה)'!חסכון_נוכחי_2023*(1+F$21)^'תכנון פרישה (מקסימום תשואה)'!שנות_עבודה_שנותרו) -> 2923739.1 | G28: =-FV(G$21,'תכנון פרישה (מקסימום תשואה)'!שנות_עבודה_שנותרו,$D$15*12*$A28)+('תכנון פרישה (מקסימום תשואה)'!חסכון_נוכחי_2023*(1+G$21)^'תכנון פרישה (מקסימום תשואה)'!שנות_עבודה_שנותרו) -> 3035997.7
A29: כמה נמשוך רק מהתשואה בגיל פרישה | B29: =B28*B$21/12 -> 6296.2076 | C29: =C28*C$21/12 -> 8711.8823 | D29: =D28*D$21/12 -> 11302.886 | E29: =E28*E$21/12 -> 14080.142 | F29: =F28*F$21/12 -> 17055.145 | G29: =G28*G$21/12 -> 20239.984
A30: ="כמה נמשוך כולל הקרן , מהפרישה ועד גיל "&$E$4&"" -> כמה נמשוך כולל הקרן , מהפרישה ועד גיל 60 | B30: =-PMT(B$21,'תכנון פרישה (מקסימום תשואה)'!גיל_הפנסיה-'תכנון פרישה (מקסימום תשואה)'!הגיל_שלנו_2023-'תכנון פרישה (מקסימום תשואה)'!שנות_עבודה_שנותרו,B28)/12 -> 12052.593 | C30: =-PMT(C$21,'תכנון פרישה (מקסימום תשואה)'!גיל_הפנסיה-'תכנון פרישה (מקסימום תשואה)'!הגיל_שלנו_2023-'תכנון פרישה (מקסימום תשואה)'!שנות_עבודה_שנותרו,C28)/12 -> 13941.617 | D30: =-PMT(D$21,'תכנון פרישה (מקסימום תשואה)'!גיל_הפנסיה-'תכנון פרישה (מקסימום תשואה)'!הגיל_שלנו_2023-'תכנון פרישה (מקסימום תשואה)'!שנות_עבודה_שנותרו,D28)/12 -> 16039.35 | E30: =-PMT(E$21,'תכנון פרישה (מקסימום תשואה)'!גיל_הפנסיה-'תכנון פרישה (מקסימום תשואה)'!הגיל_שלנו_2023-'תכנון פרישה (מקסימום תשואה)'!שנות_עבודה_שנותרו,E28)/12 -> 18357.388 | F30: =-PMT(F$21,'תכנון פרישה (מקסימום תשואה)'!גיל_הפנסיה-'תכנון פרישה (מקסימום תשואה)'!הגיל_שלנו_2023-'תכנון פרישה (מקסימום תשואה)'!שנות_עבודה_שנותרו,F28)/12 -> 20907.297 | G30: =-PMT(G$21,'תכנון פרישה (מקסימום תשואה)'!גיל_הפנסיה-'תכנון פרישה (מקסימום תשואה)'!הגיל_שלנו_2023-'תכנון פרישה (מקסימום תשואה)'!שנות_עבודה_שנותרו,G28)/12 -> 23700.713
A31: 0.25 | B31: =-FV(B$21,'תכנון פרישה (מקסימום תשואה)'!שנות_עבודה_שנותרו,$D$15*12*$A31)+('תכנון פרישה (מקסימום תשואה)'!חסכון_נוכחי_2023*(1+B$21)^'תכנון פרישה (מקסימום תשואה)'!שנות_עבודה_שנותרו) -> 3125935.3 | C31: =-FV(C$21,'תכנון פרישה (מקסימום תשואה)'!שנות_עבודה_שנותרו,$D$15*12*$A31)+('תכנון פרישה (מקסימום תשואה)'!חסכון_נוכחי_2023*(1+C$21)^'תכנון פרישה (מקסימום תשואה)'!שנות_עבודה_שנותרו) -> 3243005.9 | D31: =-FV(D$21,'תכנון פרישה (מקסימום תשואה)'!שנות_עבודה_שנותרו,$D$15*12*$A31)+('תכנון פרישה (מקסימום תשואה)'!חסכון_נוכחי_2023*(1+D$21)^'תכנון פרישה (מקסימום תשואה)'!שנות_עבודה_שנותרו) -> 3365010.3 | E31: =-FV(E$21,'תכנון פרישה (מקסימום תשואה)'!שנות_עבודה_שנותרו,$D$15*12*$A31)+('תכנון פרישה (מקסימום תשואה)'!חסכון_נוכחי_2023*(1+E$21)^'תכנון פרישה (מקסימום תשואה)'!שנות_עבודה_שנותרו) -> 3492143.1 | F31: =-FV(F$21,'תכנון פרישה (מקסימום תשואה)'!שנות_עבודה_שנותרו,$D$15*12*$A31)+('תכנון פרישה (מקסימום תשואה)'!חסכון_נוכחי_2023*(1+F$21)^'תכנון פרישה (מקסימום תשואה)'!שנות_עבודה_שנותרו) -> 3624605.6 | G31: =-FV(G$21,'תכנון פרישה (מקסימום תשואה)'!שנות_עבודה_שנותרו,$D$15*12*$A31)+('תכנון פרישה (מקסימום תשואה)'!חסכון_נוכחי_2023*(1+G$21)^'תכנון פרישה (מקסימום תשואה)'!שנות_עבודה_שנותרו) -> 3762605.8
A32: כמה נמשוך רק מהתשואה בגיל פרישה | B32: =B31*B$21/12 -> 7814.8383 | C32: =C31*C$21/12 -> 10810.02 | D32: =D31*D$21/12 -> 14020.876 | E32: =E31*E$21/12 -> 17460.715 | F32: =F31*F$21/12 -> 21143.533 | G32: =G31*G$21/12 -> 25084.039
A33: ="כמה נמשוך כולל הקרן , מהפרישה ועד גיל "&$E$4&"" -> כמה נמשוך כולל הקרן , מהפרישה ועד גיל 60 | B33: =-PMT(B$21,'תכנון פרישה (מקסימום תשואה)'!גיל_הפנסיה-'תכנון פרישה (מקסימום תשואה)'!הגיל_שלנו_2023-'תכנון פרישה (מקסימום תשואה)'!שנות_עבודה_שנותרו,B31)/12 -> 14959.651 | C33: =-PMT(C$21,'תכנון פרישה (מקסימום תשואה)'!גיל_הפנסיה-'תכנון פרישה (מקסימום תשואה)'!הגיל_שלנו_2023-'תכנון פרישה (מקסימום תשואה)'!שנות_עבודה_שנותרו,C31)/12 -> 17299.264 | D33: =-PMT(D$21,'תכנון פרישה (מקסימום תשואה)'!גיל_הפנסיה-'תכנון פרישה (מקסימום תשואה)'!הגיל_שלנו_2023-'תכנון פרישה (מקסימום תשואה)'!שנות_עבודה_שנותרו,D31)/12 -> 19896.312 | E33: =-PMT(E$21,'תכנון פרישה (מקסימום תשואה)'!גיל_הפנסיה-'תכנון פרישה (מקסימום תשואה)'!הגיל_שלנו_2023-'תכנון פרישה (מקסימום תשואה)'!שנות_עבודה_שנותרו,E31)/12 -> 22764.908 | F33: =-PMT(F$21,'תכנון פרישה (מקסימום תשואה)'!גיל_הפנסיה-'תכנון פרישה (מקסימום תשואה)'!הגיל_שלנו_2023-'תכנון פרישה (מקסימום תשואה)'!שנות_עבודה_שנותרו,F31)/12 -> 25919.107 | G33: =-PMT(G$21,'תכנון פרישה (מקסימום תשואה)'!גיל_הפנסיה-'תכנון פרישה (מקסימום תשואה)'!הגיל_שלנו_2023-'תכנון פרישה (מקסימום תשואה)'!שנות_עבודה_שנותרו,G31)/12 -> 29373.027
A34: 0.3 | B34: =-FV(B$21,'תכנון פרישה (מקסימום תשואה)'!שנות_עבודה_שנותרו,$D$15*12*$A34)+('תכנון פרישה (מקסימום תשואה)'!חסכון_נוכחי_2023*(1+B$21)^'תכנון פרישה (מקסימום תשואה)'!שנות_עבודה_שנותרו) -> 3733387.6 | C34: =-FV(C$21,'תכנון פרישה (מקסימום תשואה)'!שנות_עבודה_שנותרו,$D$15*12*$A34)+('תכנון פרישה (מקסימום תשואה)'!חסכון_נוכחי_2023*(1+C$21)^'תכנון פרישה (מקסימום תשואה)'!שנות_עבודה_שנותרו) -> 3872447.1 | D34: =-FV(D$21,'תכנון פרישה (מקסימום תשואה)'!שנות_עבודה_שנותרו,$D$15*12*$A34)+('תכנון פרישה (מקסימום תשואה)'!חסכון_נוכחי_2023*(1+D$21)^'תכנון פרישה (מקסימום תשואה)'!שנות_עבודה_שנותרו) -> 4017328 | E34: =-FV(E$21,'תכנון פרישה (מקסימום תשואה)'!שנות_עבודה_שנותרו,$D$15*12*$A34)+('תכנון פרישה (מקסימום תשואה)'!חסכון_נוכחי_2023*(1+E$21)^'תכנון פרישה (מקסימום תשואה)'!שנות_עבודה_שנותרו) -> 4168257.8 | F34: =-FV(F$21,'תכנון פרישה (מקסימום תשואה)'!שנות_עבודה_שנותרו,$D$15*12*$A34)+('תכנון פרישה (מקסימום תשואה)'!חסכון_נוכחי_2023*(1+F$21)^'תכנון פרישה (מקסימום תשואה)'!שנות_עבודה_שנותרו) -> 4325472.1 | G34: =-FV(G$21,'תכנון פרישה (מקסימום תשואה)'!שנות_עבודה_שנותרו,$D$15*12*$A34)+('תכנון פרישה (מקסימום תשואה)'!חסכון_נוכחי_2023*(1+G$21)^'תכנון פרישה (מקסימום תשואה)'!שנות_עבודה_שנותרו) -> 4489214
A35: כמה נמשוך רק מהתשואה בגיל פרישה | B35: =B34*B$21/12 -> 9333.469 | C35: =C34*C$21/12 -> 12908.157 | D35: =D34*D$21/12 -> 16738.866 | E35: =E34*E$21/12 -> 20841.289 | F35: =F34*F$21/12 -> 25231.92 | G35: =G34*G$21/12 -> 29928.093
A36: ="כמה נמשוך כולל הקרן , מהפרישה ועד גיל "&$E$4&"" -> כמה נמשוך כולל הקרן , מהפרישה ועד גיל 60 | B36: =-PMT(B$21,'תכנון פרישה (מקסימום תשואה)'!גיל_הפנסיה-'תכנון פרישה (מקסימום תשואה)'!הגיל_שלנו_2023-'תכנון פרישה (מקסימום תשואה)'!שנות_עבודה_שנותרו,B34)/12 -> 17866.709 | C36: =-PMT(C$21,'תכנון פרישה (מקסימום תשואה)'!גיל_הפנסיה-'תכנון פרישה (מקסימום תשואה)'!הגיל_שלנו_2023-'תכנון פרישה (מקסימום תשואה)'!שנות_עבודה_שנותרו,C34)/12 -> 20656.912 | D36: =-PMT(D$21,'תכנון פרישה (מקסימום תשואה)'!גיל_הפנסיה-'תכנון פרישה (מקסימום תשואה)'!הגיל_שלנו_2023-'תכנון פרישה (מקסימום תשואה)'!שנות_עבודה_שנותרו,D34)/12 -> 23753.274 | E36: =-PMT(E$21,'תכנון פרישה (מקסימום תשואה)'!גיל_הפנסיה-'תכנון פרישה (מקסימום תשואה)'!הגיל_שלנו_2023-'תכנון פרישה (מקסימום תשואה)'!שנות_עבודה_שנותרו,E34)/12 -> 27172.427 | F36: =-PMT(F$21,'תכנון פרישה (מקסימום תשואה)'!גיל_הפנסיה-'תכנון פרישה (מקסימום תשואה)'!הגיל_שלנו_2023-'תכנון פרישה (מקסימום תשואה)'!שנות_עבודה_שנותרו,F34)/12 -> 30930.916 | G36: =-PMT(G$21,'תכנון פרישה (מקסימום תשואה)'!גיל_הפנסיה-'תכנון פרישה (מקסימום תשואה)'!הגיל_שלנו_2023-'תכנון פרישה (מקסימום תשואה)'!שנות_עבודה_שנותרו,G34)/12 -> 35045.34
A37: 0.35 | B37: =-FV(B$21,'תכנון פרישה (מקסימום תשואה)'!שנות_עבודה_שנותרו,$D$15*12*$A37)+('תכנון פרישה (מקסימום תשואה)'!חסכון_נוכחי_2023*(1+B$21)^'תכנון פרישה (מקסימום תשואה)'!שנות_עבודה_שנותרו) -> 4340839.9 | C37: =-FV(C$21,'תכנון פרישה (מקסימום תשואה)'!שנות_עבודה_שנותרו,$D$15*12*$A37)+('תכנון פרישה (מקסימום תשואה)'!חסכון_נוכחי_2023*(1+C$21)^'תכנון פרישה (מקסימום תשואה)'!שנות_עבודה_שנותרו) -> 4501888.3 | D37: =-FV(D$21,'תכנון פרישה (מקסימום תשואה)'!שנות_עבודה_שנותרו,$D$15*12*$A37)+('תכנון פרישה (מקסימום תשואה)'!חסכון_נוכחי_2023*(1+D$21)^'תכנון פרישה (מקסימום תשואה)'!שנות_עבודה_שנותרו) -> 4669645.6 | E37: =-FV(E$21,'תכנון פרישה (מקסימום תשואה)'!שנות_עבודה_שנותרו,$D$15*12*$A37)+('תכנון פרישה (מקסימום תשואה)'!חסכון_נוכחי_2023*(1+E$21)^'תכנון פרישה (מקסימום תשואה)'!שנות_עבודה_שנותרו) -> 4844372.6 | F37: =-FV(F$21,'תכנון פרישה (מקסימום תשואה)'!שנות_עבודה_שנותרו,$D$15*12*$A37)+('תכנון פרישה (מקסימום תשואה)'!חסכון_נוכחי_2023*(1+F$21)^'תכנון פרישה (מקסימום תשואה)'!שנות_עבודה_שנותרו) -> 5026338.6 | G37: =-FV(G$21,'תכנון פרישה (מקסימום תשואה)'!שנות_עבודה_שנותרו,$D$15*12*$A37)+('תכנון פרישה (מקסימום תשואה)'!חסכון_נוכחי_2023*(1+G$21)^'תכנון פרישה (מקסימום תשואה)'!שנות_עבודה_שנותרו) -> 5215822.1
A38: כמה נמשוך רק מהתשואה בגיל פרישה | B38: =B37*B$21/12 -> 10852.1 | C38: =C37*C$21/12 -> 15006.294 | D38: =D37*D$21/12 -> 19456.857 | E38: =E37*E$21/12 -> 24221.863 | F38: =F37*F$21/12 -> 29320.308 | G38: =G37*G$21/12 -> 34772.147
A39: ="כמה נמשוך כולל הקרן , מהפרישה ועד גיל "&$E$4&"" -> כמה נמשוך כולל הקרן , מהפרישה ועד גיל 60 | B39: =-PMT(B$21,'תכנון פרישה (מקסימום תשואה)'!גיל_הפנסיה-'תכנון פרישה (מקסימום תשואה)'!הגיל_שלנו_2023-'תכנון פרישה (מקסימום תשואה)'!שנות_עבודה_שנותרו,B37)/12 -> 20773.766 | C39: =-PMT(C$21,'תכנון פרישה (מקסימום תשואה)'!גיל_הפנסיה-'תכנון פרישה (מקסימום תשואה)'!הגיל_שלנו_2023-'תכנון פרישה (מקסימום תשואה)'!שנות_עבודה_שנותרו,C37)/12 -> 24014.559 | D39: =-PMT(D$21,'תכנון פרישה (מקסימום תשואה)'!גיל_הפנסיה-'תכנון פרישה (מקסימום תשואה)'!הגיל_שלנו_2023-'תכנון פרישה (מקסימום תשואה)'!שנות_עבודה_שנותרו,D37)/12 -> 27610.236 | E39: =-PMT(E$21,'תכנון פרישה (מקסימום תשואה)'!גיל_הפנסיה-'תכנון פרישה (מקסימום תשואה)'!הגיל_שלנו_2023-'תכנון פרישה (מקסימום תשואה)'!שנות_עבודה_שנותרו,E37)/12 -> 31579.947 | F39: =-PMT(F$21,'תכנון פרישה (מקסימום תשואה)'!גיל_הפנסיה-'תכנון פרישה (מקסימום תשואה)'!הגיל_שלנו_2023-'תכנון פרישה (מקסימום תשואה)'!שנות_עבודה_שנותרו,F37)/12 -> 35942.726 | G39: =-PMT(G$21,'תכנון פרישה (מקסימום תשואה)'!גיל_הפנסיה-'תכנון פרישה (מקסימום תשואה)'!הגיל_שלנו_2023-'תכנון פרישה (מקסימום תשואה)'!שנות_עבודה_שנותרו,G37)/12 -> 40717.654
A40: 0.4 | B40: =-FV(B$21,'תכנון פרישה (מקסימום תשואה)'!שנות_עבודה_שנותרו,$D$15*12*$A40)+('תכנון פרישה (מקסימום תשואה)'!חסכון_נוכחי_2023*(1+B$21)^'תכנון פרישה (מקסימום תשואה)'!שנות_עבודה_שנותרו) -> 4948292.2 | C40: =-FV(C$21,'תכנון פרישה (מקסימום תשואה)'!שנות_עבודה_שנותרו,$D$15*12*$A40)+('תכנון פרישה (מקסימום תשואה)'!חסכון_נוכחי_2023*(1+C$21)^'תכנון פרישה (מקסימום תשואה)'!שנות_עבודה_שנותרו) -> 5131329.5 | D40: =-FV(D$21,'תכנון פרישה (מקסימום תשואה)'!שנות_עבודה_שנותרו,$D$15*12*$A40)+('תכנון פרישה (מקסימום תשואה)'!חסכון_נוכחי_2023*(1+D$21)^'תכנון פרישה (מקסימום תשואה)'!שנות_עבודה_שנותרו) -> 5321963.3 | E40: =-FV(E$21,'תכנון פרישה (מקסימום תשואה)'!שנות_עבודה_שנותרו,$D$15*12*$A40)+('תכנון פרישה (מקסימום תשואה)'!חסכון_נוכחי_2023*(1+E$21)^'תכנון פרישה (מקסימום תשואה)'!שנות_עבודה_שנותרו) -> 5520487.3 | F40: =-FV(F$21,'תכנון פרישה (מקסימום תשואה)'!שנות_עבודה_שנותרו,$D$15*12*$A40)+('תכנון פרישה (מקסימום תשואה)'!חסכון_נוכחי_2023*(1+F$21)^'תכנון פרישה (מקסימום תשואה)'!שנות_עבודה_שנותרו) -> 5727205.1 | G40: =-FV(G$21,'תכנון פרישה (מקסימום תשואה)'!שנות_עבודה_שנותרו,$D$15*12*$A40)+('תכנון פרישה (מקסימום תשואה)'!חסכון_נוכחי_2023*(1+G$21)^'תכנון פרישה (מקסימום תשואה)'!שנות_עבודה_שנותרו) -> 5942430.2
A41: כמה נמשוך רק מהתשואה בגיל פרישה | B41: =B40*B$21/12 -> 12370.73 | C41: =C40*C$21/12 -> 17104.432 | D41: =D40*D$21/12 -> 22174.847 | E41: =E40*E$21/12 -> 27602.437 | F41: =F40*F$21/12 -> 33408.696 | G41: =G40*G$21/12 -> 39616.202
...

Sheet תכנון פרישה (מינימום תשואה)
I1: מהפרישה המוקדמת ועד גיל הפרישה (הפנסיה) | O1: בפנסיה
A2: שנות עבודה עד הפרישה | B2: 11 | D2: הכנסה חודשית ברוטו מפרישה ועד גיל פנסיה (לרמת החיים שהתרגלנו) | E2: ='תכנון פרישה'!E2 -> 30000 | K2: חיסכון חודשי בעת העבודה | L2: מצב בעת הפרישה | Q2: מצב בעת היציאה לפנסיה
